Workbook

Sheet BENDING LEG  CHECK
D3: Input Section ( provide Input in yellow cells only ) | O3: Output Section (Output in green colour )
D5: Default Settings | L5: Force at guide, F | P5: Other Output data for reference
D6: Guide Gap if any | E6: 3 | F6: mm | L6: =12*Q11*Q10*L27/L15^3/1000 -> 4.9933703 | M6: kN
D7: Ambient Temp ( 21 Deg C is default) | E7: 21 | F7: Deg C | L7: =L6*1000/9.81 -> 509.00819 | M7: kgf | P7: Pipe OD | Q7: =VLOOKUP(E18,'STD PIPE WALL THICKNESS'!A6:B44,2,FALSE) -> 219.1 | R7: mm
P8: Pipe wall thickness | Q8: =DGET('STD PIPE WALL THICKNESS'!A6:T44,E20,E17:E18) -> 8.18 | R8: mm
P9: Pipe ID | Q9: =Q7-2*Q8 -> 202.74 | R9: mm
P10: Area moment of Inertia | Q10: =PI()*(Q7^4-Q9^4)/64 -> 30186948 | R10: mm4
P11: Elastic Modulus | Q11: =IF(E22="CS",'MATERIAL DATA'!B2/1000,'MATERIAL DATA'!H2/1000) -> 203400 | R11: N/mm2
P12: Thermal exp. coefficient | Q12: =IF(E22="CS", 'MATERIAL DATA'!C36,'MATERIAL DATA'!I36) -> 1.2506429e-05 | R12: mm./mm./C
P13: Moment | Q13: =L6*1000*L15/2 -> 33336913 | R13: N-mm
L14: Bending Leg required, L | P14: Induced Stress( Unitensified) | Q14: =Q13/(Q10/(Q7/2)) -> 120.98139 | R14: N/mm2
D15: Select 5 Input data | H15: L | L15: =SQRT(3*Q11*L27*Q7/Q17) -> 13352.47 | M15: mm | P15: Hot allowable stress, Sh | Q15: =IF(E22="CS",'MATERIAL DATA'!C44/1000,'MATERIAL DATA'!I44/1000) -> 133.21343 | R15: N/mm2
P16: Cold allowable stress, Sc | Q16: 137.892 | R16: N/mm2
E17: NPS | P17: Expansion stress allowable ( 1.25 Sc + 0.25 Sh) | Q17: =(1.25*Q16+0.25*Q15)/Q18 -> 120.98139 | R17: N/mm2
D18: Nominal Pipe Size | E18: 8 | F18: inch | P18: SIF Inplane | Q18: 1.7 | R18: unitless
D20: Schedule | E20: STD
D22: Material | E22: CS
D24: Design Temperature | E24: 240 | F24: OC
P25: Assumptions:
L26: Thermal movement, D | P26: 1. Doesnot include stress intensification factors
E27: A | L27: =Q12*E30*(E24-E7)-(E6) -> 161.33447 | M27: mm | P27: 2. Uses guided Cantilever method
P28: 3. Suitable only for non critical Lines < = 6"NPS and wall thickness greater than 10S
D30: Length from anchor/ Limit stop to free end | E30: 60000 | F30: mm

Sheet MATERIAL  DATA
C1: A106 GRB | I1: A312 TP304 | M1: Ambient
A2: COLD MODULUS | B2: 203400000 | C2: KPa | G2: COLD MODULUS | H2: 195100000 | I2: KPa
A3: TEMPERATURE | B3: EXP | C3: ALLOWABLE | D3: MODULUS | E3: YIELD | G3: TEMPERATURE | H3: EXP | I3: ALLOWABLE | J3: MODULUS | K3: YIELD | M3: -30
A4: C | B4: mm./mm./C | C4: KPa | D4: KPa | E4: KPa | G4: C | H4: mm./mm./C | I4: KPa | J4: KPa | K4: KPa | M4: =M3+1 -> -29
A5: -198 | B5: 8.9993e-06 | C5: 137892 | D5: 216490000 | E5: 241311 | G5: -198 | H5: 1.4669e-05 | I5: 137892 | J5: 208910000 | K5: 206838 | M5: =M4+1 -> -28
A6: -129 | B6: 9.6292e-06 | C6: 137892 | D6: 212350000 | E6: 241311 | G6: -129 | H6: 1.5245e-05 | I6: 137892 | J6: 204770000 | K6: 206838 | M6: =M5+1 -> -27
A7: -101 | B7: 9.8992e-06 | C7: 137892 | D7: 208220000 | E7: 241311 | G7: -73 | H7: 1.5749e-05 | I7: 137892 | J7: 199940000 | K7: 206838 | M7: =M6+1 -> -26
A8: -46 | B8: 1.0439e-05 | C8: 137892 | D8: 206150000 | E8: 241311 | G8: -46 | H8: 1.6019e-05 | I8: 137892 | J8: 197880000 | K8: 206838 | M8: =M7+1 -> -25
A9: 21 | B9: 1.0925e-05 | C9: 137892 | D9: 203390000 | E9: 241311 | G9: 21 | H9: 1.6397e-05 | I9: 137892 | J9: 195120000 | K9: 206838 | M9: =M8+1 -> -24
A10: 38 | B10: 1.1033e-05 | C10: 137892 | D10: 202700000 | E10: 241311 | G10: 38 | H10: 1.6487e-05 | I10: 137892 | J10: 193740000 | K10: 206838 | M10: =M9+1 -> -23
A11: 93 | B11: 1.1483e-05 | C11: 137892 | D11: 198560000 | E11: 221317 | G11: 93 | H11: 1.6811e-05 | I11: 137892 | J11: 190290000 | K11: 172365 | M11: =M10+1 -> -22
A12: 149 | B12: 1.1879e-05 | C12: 137892 | D12: 195120000 | E12: 213733 | G12: 149 | H12: 1.7045e-05 | I12: 137892 | J12: 186150000 | K12: 154439 | M12: =M11+1 -> -21
A13: 204 | B13: 1.2275e-05 | C13: 137203 | D13: 190980000 | E13: 206149 | G13: 204 | H13: 1.7261e-05 | I13: 128240 | J13: 182710000 | K13: 142718 | M13: =M12+1 -> -20
A14: 260 | B14: 1.2635e-05 | C14: 130997 | D14: 188220000 | E14: 196496 | G14: 260 | H14: 1.7459e-05 | I14: 120656 | J14: 177880000 | K14: 133755 | M14: =M13+1 -> -19
A15: 316 | B15: 1.3013e-05 | C15: 123413 | D15: 184090000 | E15: 184775 | G15: 316 | H15: 1.7675e-05 | I15: 114450 | J15: 174430000 | K15: 126861 | M15: =M14+1 -> -18
A16: 343 | B16: 1.3193e-05 | C16: 119277 | D16: 179950000 | E16: 178570 | G16: 343 | H16: 1.7765e-05 | I16: 111693 | J16: 172360000 | K16: 124103 | M16: =M15+1 -> -17
... A23: 538 | B23: 1.4345e-05 | C23: 17236 | D23: 140650000 | E23: 143408 | G23: 538 | H23: 1.8521e-05 | I23: 96524 | J23: 157200000 | K23: 106866 | M23: =M22+1 -> -10
A24: 566 | B24: 1.4489e-05 | C24: 11031 | D24: 132380000 | G24: 566 | H24: 1.8611e-05 | I24: 85493 | J24: 154440000 | M24: =M23+1 -> -9
A25: 593 | B25: 1.4615e-05 | C25: 6895 | D25: 124100000 | G25: 593 | H25: 1.8701e-05 | I25: 67567 | J25: 152370000 | M25: =M24+1 -> -8
A26: 621 | B26: 1.4687e-05 | G26: 621 | H26: 1.879e-05 | I26: 53088 | J26: 148920000 | M26: =M25+1 -> -7
A27: 649 | B27: 1.4741e-05 | G27: 649 | H27: 1.8862e-05 | I27: 42057 | J27: 146170000 | M27: =M26+1 -> -6
A28: 677 | B28: 1.4831e-05 | G28: 677 | H28: 1.8916e-05 | I28: 32405 | J28: 142720000 | M28: =M27+1 -> -5
A29: 705 | B29: 1.4903e-05 | G29: 705 | H29: 1.897e-05 | I29: 25510 | J29: 139270000 | M29: =M28+1 -> -4
A30: 732 | B30: 1.4975e-05 | G30: 732 | H30: 1.9024e-05 | I30: 19994 | J30: 135820000 | M30: =M29+1 -> -3
A31: 760 | B31: 1.5047e-05 | G31: 760 | H31: 1.9078e-05 | I31: 15858 | J31: 132380000 | M31: =M30+1 -> -2
G32: 788 | H32: 1.9222e-05 | I32: 12410 | J32: 128240000 | M32: =M31+1 -> -1
G33: 816 | H33: 1.9384e-05 | I33: 9652 | J33: 124790000 | M33: =M32+1 -> 0
M34: =M33+1 -> 1
C35: E | M35: =M34+1 -> 2
A36: User Value | B36: ='BENDING LEG CHECK'!E24 -> 240 | C36: =IF(C38=C39,C38,C38+(C39-C38)/(B39-B38)*(B36-B38)) -> 1.2506429e-05 | G36: User Value | H36: ='BENDING LEG CHECK'!E24 -> 240 | I36: =IF(I38=I39,I38,I38+(I39-I38)/(H39-H38)*(H36-H38)) -> 1.7388286e-05 | M36: =M35+1 -> 3
M37: =M36+1 -> 4
B38: =VLOOKUP(B36,A3:B31,1,TRUE) -> 204 | C38: =VLOOKUP(B38,A3:B31,2,FALSE) -> 1.2275e-05 | H38: =VLOOKUP(H36,G3:H33,1,TRUE) -> 204 | I38: =VLOOKUP(H38,G3:H33,2,FALSE) -> 1.7261e-05 | M38: =M37+1 -> 5
B39: =SMALL(A5:A31,COUNTIF(A5:A31,"<"&B36)+1) -> 260 | C39: =VLOOKUP(B39,A3:B31,2,FALSE) -> 1.2635e-05 | H39: =SMALL(G5:G33,COUNTIF(G5:G33,"<"&H36)+1) -> 260 | I39: =VLOOKUP(H39,G3:H33,2,FALSE) -> 1.7459e-05 | M39: =M38+1 -> 6
M40: =M39+1 -> 7
M41: =M40+1 -> 8
M42: =M41+1 -> 9
C43: E | M43: =M42+1 -> 10
A44: User Value | B44: ='BENDING LEG CHECK'!E24 -> 240 | C44: =IF(C46=C47,C46,C46+(C47-C46)/(B47-B46)*(B44-B46)) -> 133213.43 | G44: User Value | H44: ='BENDING LEG CHECK'!E24 -> 240 | I44: =IF(I46=I47,I46,I46+(I47-I46)/(H47-H46)*(H44-H46)) -> 123364.57 | M44: =M43+1 -> 11
M45: =M44+1 -> 12
B46: =VLOOKUP(B44,A3:B31,1,TRUE) -> 204 | C46: =VLOOKUP(B46,A5:C25,3,FALSE) -> 137203 | H46: =VLOOKUP(H44,G3:H33,1,TRUE) -> 204 | I46: =VLOOKUP(H46,G5:I33,3,FALSE) -> 128240 | M46: =M45+1 -> 13
...

Sheet STD PIPE WALL THICKNESS
D2: STANDARD PIPE WALL THICKNESS AS PER ASME B36.10M & B36.19M
D3: (SCHEDULED THICKNESSES)
C5: SCHEDULE NO
A6: NPS | B6: OD | C6: SCH5 | D6: 5S | E6: SCH10 | F6: 10S | G6: SCH20 | H6: SCH30 | I6: STD | J6: SCH40 | K6: 40S | L6: SCH60 | M6: XS | N6: SCH80 | O6: 80S | P6: SCH100 | Q6: SCH120 | R6: SCH140 | S6: SCH160 | T6: XXS
A7: 0.5 | B7: 21.3 | C7: 1.65 | D7: 1.65 | E7: 2.11 | F7: 2.11 | H7: 2.41 | I7: 2.77 | J7: 2.77 | K7: 2.77 | M7: 3.73 | N7: 3.73 | O7: 3.73 | S7: 4.78 | T7: 7.47
A8: 0.75 | B8: 26.7 | C8: 1.65 | D8: 1.65 | E8: 2.11 | F8: 2.11 | H8: 2.41 | I8: 2.87 | J8: 2.87 | K8: 2.87 | M8: 3.91 | N8: 3.91 | O8: 3.91 | S8: 5.56 | T8: 7.82
A9: 1 | B9: 33.4 | C9: 1.65 | D9: 1.65 | E9: 2.77 | F9: 2.77 | H9: 2.9 | I9: 3.38 | J9: 3.38 | K9: 3.38 | M9: 4.55 | N9: 4.55 | O9: 4.55 | S9: 6.35 | T9: 9.09
A10: 1.5 | B10: 48.3 | C10: 1.65 | D10: 1.65 | E10: 2.77 | F10: 2.77 | H10: 3.18 | I10: 3.68 | J10: 3.68 | K10: 3.68 | M10: 5.08 | N10: 5.08 | O10: 5.08 | S10: 7.14 | T10: 10.15
A11: 2 | B11: 60.3 | C11: 1.65 | D11: 1.65 | E11: 2.77 | F11: 2.77 | H11: 3.18 | I11: 3.91 | J11: 3.91 | K11: 3.91 | M11: 5.54 | N11: 5.54 | O11: 5.54 | S11: 8.74 | T11: 11.07
A12: 2.5 | B12: 73 | C12: 2.11 | D12: 2.11 | E12: 3.05 | F12: 3.05 | H12: 4.78 | I12: 5.16 | J12: 5.16 | K12: 5.16 | M12: 7.01 | N12: 7.01 | O12: 7.01 | S12: 9.53 | T12: 14.02
A13: 3 | B13: 88.9 | C13: 2.11 | D13: 2.11 | E13: 3.05 | F13: 3.05 | H13: 4.78 | I13: 5.49 | J13: 5.49 | K13: 5.49 | M13: 7.62 | N13: 7.62 | O13: 7.62 | S13: 11.13 | T13: 15.24
A14: 4 | B14: 114.3 | C14: 2.11 | D14: 2.11 | E14: 3.05 | F14: 3.05 | H14: 4.78 | I14: 6.02 | J14: 6.02 | K14: 6.02 | M14: 8.56 | N14: 8.56 | O14: 8.56 | Q14: 11.13 | S14: 13.49 | T14: 17.12
A15: 6 | B15: 168.3 | C15: 2.77 | D15: 2.77 | E15: 3.4 | F15: 3.4 | I15: 7.11 | J15: 7.11 | K15: 7.11 | M15: 10.97 | N15: 10.97 | O15: 10.97 | Q15: 14.27 | S15: 18.26 | T15: 21.95
A16: 8 | B16: 219.1 | C16: 2.77 | D16: 2.77 | E16: 3.76 | F16: 3.76 | G16: 6.35 | H16: 7.04 | I16: 8.18 | J16: 8.18 | K16: 8.18 | L16: 10.31 | M16: 12.7 | N16: 12.7 | O16: 12.7 | P16: 15.09 | Q16: 18.26 | R16: 20.62 | S16: 23.01 | T16: 22.23
A17: 10 | B17: 273 | C17: 3.4 | D17: 3.4 | E17: 4.19 | F17: 4.19 | G17: 6.35 | H17: 7.8 | I17: 9.27 | J17: 9.27 | K17: 9.27 | L17: 12.7 | M17: 12.7 | N17: 15.09 | O17: 12.7 | P17: 18.26 | Q17: 21.44 | R17: 25.4 | S17: 28.58 | T17: 25.4
A18: 12 | B18: 323.8 | C18: 3.96 | D18: 3.96 | E18: 4.57 | F18: 4.57 | G18: 6.35 | H18: 8.38 | I18: 9.53 | J18: 10.31 | K18: 9.53 | L18: 14.27 | M18: 12.7 | N18: 17.48 | O18: 12.7 | P18: 21.44 | Q18: 25.4 | R18: 28.58 | S18: 33.32 | T18: 25.4
A19: 14 | B19: 355.6 | C19: 3.96 | D19: 3.96 | E19: 6.35 | F19: 4.78 | G19: 7.92 | H19: 9.53 | I19: 9.53 | J19: 11.13 | K19: 9.53 | L19: 15.09 | M19: 12.7 | N19: 19.05 | O19: 12.7 | P19: 23.83 | Q19: 27.79 | R19: 31.75 | S19: 35.71
A20: 16 | B20: 406.4 | C20: 4.19 | D20: 4.19 | E20: 6.35 | F20: 4.78 | G20: 7.92 | H20: 9.53 | I20: 9.53 | J20: 12.7 | K20: 9.53 | L20: 16.66 | M20: 12.7 | N20: 21.44 | O20: 12.7 | P20: 26.19 | Q20: 30.96 | R20: 36.53 | S20: 40.49
A21: 18 | B21: 457 | C21: 4.19 | D21: 4.19 | E21: 6.35 | F21: 4.78 | G21: 7.92 | H21: 11.13 | I21: 9.53 | J21: 14.27 | K21: 9.53 | L21: 19.05 | M21: 12.7 | N21: 23.83 | O21: 12.7 | P21: 29.36 | Q21: 34.93 | R21: 39.67 | S21: 45.24
A22: 20 | B22: 508 | C22: 4.78 | D22: 4.78 | E22: 6.35 | F22: 5.54 | G22: 9.53 | H22: 12.7 | I22: 9.53 | J22: 15.09 | K22: 9.53 | L22: 20.62 | M22: 12.7 | N22: 26.19 | O22: 12.7 | P22: 32.54 | Q22: 38.1 | R22: 44.45 | S22: 50.01
A23: 22 | B23: 559 | C23: 4.78 | D23: 4.78 | E23: 6.35 | F23: 5.54 | G23: 9.53 | H23: 12.7 | I23: 9.53 | L23: 22.23 | M23: 12.7 | N23: 28.58 | P23: 34.93 | Q23: 41.28 | R23: 47.63 | S23: 53.98
A24: 24 | B24: 610 | C24: 5.54 | D24: 5.54 | E24: 6.35 | F24: 6.35 | G24: 9.53 | H24: 14.27 | I24: 9.53 | J24: 17.48 | K24: 9.53 | L24: 24.61 | M24: 12.7 | N24: 30.96 | O24: 12.7 | P24: 38.89 | Q24: 46.02 | R24: 52.37 | S24: 59.54
A25: 26 | B25: 660 | E25: 7.92 | G25: 12.7 | I25: 9.53 | M25: 12.7
A26: 28 | B26: 711 | E26: 7.92 | G26: 12.7 | H26: 15.88 | I26: 9.53 | M26: 12.7
A27: 30 | B27: 762 | C27: 6.35 | D27: 6.35 | E27: 7.92 | F27: 7.92 | G27: 12.7 | H27: 15.88 | I27: 9.53 | M27: 12.7
A28: 32 | B28: 813 | E28: 7.92 | G28: 12.7 | H28: 15.88 | I28: 9.53 | J28: 17.48 | M28: 12.7
A29: 34 | B29: 864 | E29: 7.92 | G29: 12.7 | H29: 15.88 | I29: 9.53 | J29: 17.48 | M29: 12.7
A30: 36 | B30: 914 | E30: 7.92 | G30: 12.7 | H30: 15.88 | I30: 9.53 | J30: 19.05 | M30: 12.7
A31: 38 | B31: 965 | I31: 9.53 | M31: 12.7
A32: 40 | B32: 1016 | I32: 9.53 | M32: 12.7
A33: 42 | B33: 1067 | I33: 9.53 | M33: 12.7
A34: 44 | B34: 1118 | I34: 9.53 | M34: 12.7
A35: 46 | B35: 1168 | I35: 9.53 | M35: 12.7
A36: 48 | B36: 1219 | I36: 9.53 | M36: 12.7
A37: 52 | B37: 1321
A38: 56 | B38: 1422
A39: 60 | B39: 1524
A40: 64 | B40: 1626
A41: 68 | B41: 1727
A42: 72 | B42: 1829
...

Sheet SIF CHECK
E2: STANDARD PIPE WALL THICKNESS AS PER ASME B36.10M & B36.19M
E3: (SCHEDULED THICKNESSES)
D5: SCHEDULE NO
A6: NPS | B6: 1.5d | C6: OD | D6: SCH5 | E6: 5S | F6: SCH10 | G6: 10S | H6: SCH20 | I6: SCH30 | J6: STD | K6: SCH40 | L6: 40S | M6: SCH60 | N6: XS | O6: SCH80 | P6: 80S | Q6: SCH100 | R6: SCH120 | S6: SCH140 | T6: SCH160 | U6: XXS
A7: 0.5 | B7: =A7*25.4*1.5 -> 19.05 | C7: 21.3 | D7: 1.65 | E7: 1.65 | F7: 2.11 | G7: 2.11 | I7: 2.41 | J7: 2.77 | K7: 2.77 | L7: 2.77 | N7: 3.73 | O7: 3.73 | P7: 3.73 | T7: 4.78 | U7: 7.47
B8: =B7 -> 19.05 | C8: r mean | D8: =($C7/2)-(D7/2) -> 9.825 | E8: =($C7/2)-(E7/2) -> 9.825 | F8: =($C7/2)-(F7/2) -> 9.595 | G8: =($C7/2)-(G7/2) -> 9.595 | I8: =($C7/2)-(I7/2) -> 9.445 | J8: =($C7/2)-(J7/2) -> 9.265 | K8: =($C7/2)-(K7/2) -> 9.265 | L8: =($C7/2)-(L7/2) -> 9.265 | N8: =($C7/2)-(N7/2) -> 8.785 | O8: =($C7/2)-(O7/2) -> 8.785 | P8: =($C7/2)-(P7/2) -> 8.785 | T8: =($C7/2)-(T7/2) -> 8.26 | U8: =($C7/2)-(U7/2) -> 6.915
B9: =B7 -> 19.05 | C9: h ( for long radius bend) | D9: =D7*$B9/D8/D8 -> 0.32562205 | E9: =E7*$B9/E8/E8 -> 0.32562205 | F9: =F7*$B9/F8/F8 -> 0.43660377 | G9: =G7*$B9/G8/G8 -> 0.43660377 | I9: =I7*$B9/I8/I8 -> 0.5146454 | J9: =J7*$B9/J8/J8 -> 0.61472928 | K9: =K7*$B9/K8/K8 -> 0.61472928 | L9: =L7*$B9/L8/L8 -> 0.61472928 | N9: =N7*$B9/N8/N8 -> 0.92070453 | O9: =O7*$B9/O8/O8 -> 0.92070453 | P9: =P7*$B9/P8/P8 -> 0.92070453 | T9: =T7*$B9/T8/T8 -> 1.3346358 | U9: =U7*$B9/U8/U8 -> 2.9759883
B10: =A7 -> 0.5 | C10: SIF Inplane | D10: =0.9/(D9^0.666666) -> 1.9015145 | E10: =0.9/(E9^0.666666) -> 1.9015145 | F10: =0.9/(F9^0.666666) -> 1.5638099 | G10: =0.9/(G9^0.666666) -> 1.5638099 | I10: =0.9/(I9^0.666666) -> 1.4014263 | J10: =0.9/(J9^0.666666) -> 1.2448579 | K10: =0.9/(K9^0.666666) -> 1.2448579 | L10: =0.9/(L9^0.666666) -> 1.2448579 | N10: =0.9/(N9^0.666666) -> 0.95096011 | O10: =0.9/(O9^0.666666) -> 0.95096011 | P10: =0.9/(P9^0.666666) -> 0.95096011 | T10: =0.9/(T9^0.666666) -> 0.74245033 | U10: =0.9/(U9^0.666666) -> 0.43499943
A11: 0.75 | B11: =A11*25.4*1.5 -> 28.575 | C11: 26.7 | D11: 1.65 | E11: 1.65 | F11: 2.11 | G11: 2.11 | I11: 2.41 | J11: 2.87 | K11: 2.87 | L11: 2.87 | N11: 3.91 | O11: 3.91 | P11: 3.91 | T11: 5.56 | U11: 7.82
B12: =B11 -> 28.575 | C12: r mean | D12: =($C11/2)-(D11/2) -> 12.525 | E12: =($C11/2)-(E11/2) -> 12.525 | F12: =($C11/2)-(F11/2) -> 12.295 | G12: =($C11/2)-(G11/2) -> 12.295 | I12: =($C11/2)-(I11/2) -> 12.145 | J12: =($C11/2)-(J11/2) -> 11.915 | K12: =($C11/2)-(K11/2) -> 11.915 | L12: =($C11/2)-(L11/2) -> 11.915 | N12: =($C11/2)-(N11/2) -> 11.395 | O12: =($C11/2)-(O11/2) -> 11.395 | P12: =($C11/2)-(P11/2) -> 11.395 | T12: =($C11/2)-(T11/2) -> 10.57 | U12: =($C11/2)-(U11/2) -> 9.44
B13: =B11 -> 28.575 | C13: h ( for long radius bend) | D13: =D11*$B13/D12/D12 -> 0.3005486 | E13: =E11*$B13/E12/E12 -> 0.3005486 | F13: =F11*$B13/F12/F12 -> 0.39885187 | G13: =G11*$B13/G12/G12 -> 0.39885187 | I13: =I11*$B13/I12/I12 -> 0.4668832 | J13: =J11*$B13/J12/J12 -> 0.5776703 | K13: =K11*$B13/K12/K12 -> 0.5776703 | L13: =L11*$B13/L12/L12 -> 0.5776703 | N13: =N11*$B13/N12/N12 -> 0.86046723 | O13: =O11*$B13/O12/O12 -> 0.86046723 | P13: =P11*$B13/P12/P12 -> 0.86046723 | T13: =T11*$B13/T12/T12 -> 1.4220375 | U13: =U11*$B13/U12/U12 -> 2.5075465
B14: =A11 -> 0.75 | C14: SIF Inplane | D14: =0.9/(D13^0.666666) -> 2.0058526 | E14: =0.9/(E13^0.666666) -> 2.0058526 | F14: =0.9/(F13^0.666666) -> 1.6609931 | G14: =0.9/(G13^0.666666) -> 1.6609931 | I14: =0.9/(I13^0.666666) -> 1.4954439 | J14: =0.9/(J13^0.666666) -> 1.2975447 | K14: =0.9/(K13^0.666666) -> 1.2975447 | L14: =0.9/(L13^0.666666) -> 1.2975447 | N14: =0.9/(N13^0.666666) -> 0.99483924 | O14: =0.9/(O13^0.666666) -> 0.99483924 | P14: =0.9/(P13^0.666666) -> 0.99483924 | T14: =0.9/(T13^0.666666) -> 0.7117081 | U14: =0.9/(U13^0.666666) -> 0.48761468
A15: 1 | B15: =A15*25.4*1.5 -> 38.1 | C15: 33.4 | D15: 1.65 | E15: 1.65 | F15: 2.77 | G15: 2.77 | I15: 2.9 | J15: 3.38 | K15: 3.38 | L15: 3.38 | N15: 4.55 | O15: 4.55 | P15: 4.55 | T15: 6.35 | U15: 9.09
B16: =B15 -> 38.1 | C16: r mean | D16: =($C15/2)-(D15/2) -> 15.875 | E16: =($C15/2)-(E15/2) -> 15.875 | F16: =($C15/2)-(F15/2) -> 15.315 | G16: =($C15/2)-(G15/2) -> 15.315 | I16: =($C15/2)-(I15/2) -> 15.25 | J16: =($C15/2)-(J15/2) -> 15.01 | K16: =($C15/2)-(K15/2) -> 15.01 | L16: =($C15/2)-(L15/2) -> 15.01 | N16: =($C15/2)-(N15/2) -> 14.425 | O16: =($C15/2)-(O15/2) -> 14.425 | P16: =($C15/2)-(P15/2) -> 14.425 | T16: =($C15/2)-(T15/2) -> 13.525 | U16: =($C15/2)-(U15/2) -> 12.155
B17: =B15 -> 38.1 | C17: h ( for long radius bend) | D17: =D15*$B17/D16/D16 -> 0.24944882 | E17: =E15*$B17/E16/E16 -> 0.24944882 | F17: =F15*$B17/F16/F16 -> 0.44995672 | G17: =G15*$B17/G16/G16 -> 0.44995672 | I17: =I15*$B17/I16/I16 -> 0.47509809 | J17: =J15*$B17/J16/J16 -> 0.5715843 | K17: =K15*$B17/K16/K16 -> 0.5715843 | L17: =L15*$B17/L16/L16 -> 0.5715843 | N17: =N15*$B17/N16/N16 -> 0.83311457 | O17: =O15*$B17/O16/O16 -> 0.83311457 | P17: =P15*$B17/P16/P16 -> 0.83311457 | T17: =T15*$B17/T16/T16 -> 1.3225867 | U17: =U15*$B17/U16/U16 -> 2.3441151
B18: =A15 -> 1 | C18: SIF Inplane | D18: =0.9/(D17^0.666666) -> 2.2711953 | E18: =0.9/(E17^0.666666) -> 2.2711953 | F18: =0.9/(F17^0.666666) -> 1.5327163 | G18: =0.9/(G17^0.666666) -> 1.5327163 | I18: =0.9/(I17^0.666666) -> 1.4781554 | J18: =0.9/(J17^0.666666) -> 1.3067389 | K18: =0.9/(K17^0.666666) -> 1.3067389 | L18: =0.9/(L17^0.666666) -> 1.3067389 | N18: =0.9/(N17^0.666666) -> 1.0164967 | O18: =0.9/(O17^0.666666) -> 1.0164967 | P18: =0.9/(P17^0.666666) -> 1.0164967 | T18: =0.9/(T17^0.666666) -> 0.74695279 | U18: =0.9/(U17^0.666666) -> 0.51002344
A19: 1.5 | B19: =A19*25.4*1.5 -> 57.15 | C19: 48.3 | D19: 1.65 | E19: 1.65 | F19: 2.77 | G19: 2.77 | I19: 3.18 | J19: 3.68 | K19: 3.68 | L19: 3.68 | N19: 5.08 | O19: 5.08 | P19: 5.08 | T19: 7.14 | U19: 10.15
B20: =B19 -> 57.15 | C20: r mean | D20: =($C19/2)-(D19/2) -> 23.325 | E20: =($C19/2)-(E19/2) -> 23.325 | F20: =($C19/2)-(F19/2) -> 22.765 | G20: =($C19/2)-(G19/2) -> 22.765 | I20: =($C19/2)-(I19/2) -> 22.56 | J20: =($C19/2)-(J19/2) -> 22.31 | K20: =($C19/2)-(K19/2) -> 22.31 | L20: =($C19/2)-(L19/2) -> 22.31 | N20: =($C19/2)-(N19/2) -> 21.61 | O20: =($C19/2)-(O19/2) -> 21.61 | P20: =($C19/2)-(P19/2) -> 21.61 | T20: =($C19/2)-(T19/2) -> 20.58 | U20: =($C19/2)-(U19/2) -> 19.075
B21: =B19 -> 57.15 | C21: h ( for long radius bend) | D21: =D19*$B21/D20/D20 -> 0.17332327 | E21: =E19*$B21/E20/E20 -> 0.17332327 | F21: =F19*$B21/F20/F20 -> 0.30546446 | G21: =G19*$B21/G20/G20 -> 0.30546446 | I21: =I19*$B21/I20/I20 -> 0.3570797 | J21: =J19*$B21/J20/J20 -> 0.42253716 | K21: =K19*$B21/K20/K20 -> 0.42253716 | L21: =L19*$B21/L20/L20 -> 0.42253716 | N21: =N19*$B21/N20/N20 -> 0.62168503 | O21: =O19*$B21/O20/O20 -> 0.62168503 | P21: =P19*$B21/P20/P20 -> 0.62168503 | T21: =T19*$B21/T20/T20 -> 0.96343785 | U21: =U19*$B21/U20/U20 -> 1.5942381
B22: =A19 -> 1.5 | C22: SIF Inplane | D22: =0.9/(D21^0.666666) -> 2.8951479 | E22: =0.9/(E21^0.666666) -> 2.8951479 | F22: =0.9/(F21^0.666666) -> 1.9842743 | G22: =0.9/(G21^0.666666) -> 1.9842743 | I22: =0.9/(I21^0.666666) -> 1.7881287 | J22: =0.9/(J21^0.666666) -> 1.5983271 | K22: =0.9/(K21^0.666666) -> 1.5983271 | L22: =0.9/(L21^0.666666) -> 1.5983271 | N22: =0.9/(N21^0.666666) -> 1.235555 | O22: =0.9/(O21^0.666666) -> 1.235555 | P22: =0.9/(P21^0.666666) -> 1.235555 | T22: =0.9/(T21^0.666666) -> 0.92262814 | U22: =0.9/(U21^0.666666) -> 0.65948844
A23: 2 | B23: =A23*25.4*1.5 -> 76.2 | C23: 60.3 | D23: 1.65 | E23: 1.65 | F23: 2.77 | G23: 2.77 | I23: 3.18 | J23: 3.91 | K23: 3.91 | L23: 3.91 | N23: 5.54 | O23: 5.54 | P23: 5.54 | T23: 8.74 | U23: 11.07
B24: =B23 -> 76.2 | C24: r mean | D24: =($C23/2)-(D23/2) -> 29.325 | E24: =($C23/2)-(E23/2) -> 29.325 | F24: =($C23/2)-(F23/2) -> 28.765 | G24: =($C23/2)-(G23/2) -> 28.765 | I24: =($C23/2)-(I23/2) -> 28.56 | J24: =($C23/2)-(J23/2) -> 28.195 | K24: =($C23/2)-(K23/2) -> 28.195 | L24: =($C23/2)-(L23/2) -> 28.195 | N24: =($C23/2)-(N23/2) -> 27.38 | O24: =($C23/2)-(O23/2) -> 27.38 | P24: =($C23/2)-(P23/2) -> 27.38 | T24: =($C23/2)-(T23/2) -> 25.78 | U24: =($C23/2)-(U23/2) -> 24.615
B25: =B23 -> 76.2 | C25: h ( for long radius bend) | D25: =D23*$B25/D24/D24 -> 0.14620522 | E25: =E23*$B25/E24/E24 -> 0.14620522 | F25: =F23*$B25/F24/F24 -> 0.25509737 | G25: =G23*$B25/G24/G24 -> 0.25509737 | I25: =I23*$B25/I24/I24 -> 0.29707471 | J25: =J23*$B25/J24/J24 -> 0.3747896 | K25: =K23*$B25/K24/K24 -> 0.3747896 | L25: =L23*$B25/L24/L24 -> 0.3747896 | N25: =N23*$B25/N24/N24 -> 0.56311598 | O25: =O23*$B25/O24/O24 -> 0.56311598 | P25: =P23*$B25/P24/P24 -> 0.56311598 | T25: =T23*$B25/T24/T24 -> 1.0020758 | U25: =U23*$B25/U24/U24 -> 1.3922041
B26: =A23 -> 2 | C26: SIF Inplane | D26: =0.9/(D25^0.666666) -> 3.2428986 | E26: =0.9/(E25^0.666666) -> 3.2428986 | F26: =0.9/(F25^0.666666) -> 2.2375434 | G26: =0.9/(G25^0.666666) -> 2.2375434 | I26: =0.9/(I25^0.666666) -> 2.0214595 | J26: =0.9/(J25^0.666666) -> 1.731346 | K26: =0.9/(K25^0.666666) -> 1.731346 | L26: =0.9/(L25^0.666666) -> 1.731346 | N26: =0.9/(N25^0.666666) -> 1.3198071 | O26: =0.9/(O25^0.666666) -> 1.3198071 | P26: =0.9/(P25^0.666666) -> 1.3198071 | T26: =0.9/(T25^0.666666) -> 0.89875667 | U26: =0.9/(U25^0.666666) -> 0.72183953
A27: 2.5 | B27: =A27*25.4*1.5 -> 95.25 | C27: 73 | D27: 2.11 | E27: 2.11 | F27: 3.05 | G27: 3.05 | I27: 4.78 | J27: 5.16 | K27: 5.16 | L27: 5.16 | N27: 7.01 | O27: 7.01 | P27: 7.01 | T27: 9.53 | U27: 14.02
B28: =B27 -> 95.25 | C28: r mean | D28: =($C27/2)-(D27/2) -> 35.445 | E28: =($C27/2)-(E27/2) -> 35.445 | F28: =($C27/2)-(F27/2) -> 34.975 | G28: =($C27/2)-(G27/2) -> 34.975 | I28: =($C27/2)-(I27/2) -> 34.11 | J28: =($C27/2)-(J27/2) -> 33.92 | K28: =($C27/2)-(K27/2) -> 33.92 | L28: =($C27/2)-(L27/2) -> 33.92 | N28: =($C27/2)-(N27/2) -> 32.995 | O28: =($C27/2)-(O27/2) -> 32.995 | P28: =($C27/2)-(P27/2) -> 32.995 | T28: =($C27/2)-(T27/2) -> 31.735 | U28: =($C27/2)-(U27/2) -> 29.49
B29: =B27 -> 95.25 | C29: h ( for long radius bend) | D29: =D27*$B29/D28/D28 -> 0.15996961 | E29: =E27*$B29/E28/E28 -> 0.15996961 | F29: =F27*$B29/F28/F28 -> 0.23749221 | G29: =G27*$B29/G28/G28 -> 0.23749221 | I29: =I27*$B29/I28/I28 -> 0.39131765 | J29: =J27*$B29/J28/J28 -> 0.42717222 | K29: =K27*$B29/K28/K28 -> 0.42717222 | L29: =L27*$B29/L28/L28 -> 0.42717222 | N29: =N27*$B29/N28/N28 -> 0.61331945 | O29: =O27*$B29/O28/O28 -> 0.61331945 | P29: =P27*$B29/P28/P28 -> 0.61331945 | T29: =T27*$B29/T28/T28 -> 0.90132388 | U29: =U27*$B29/U28/U28 -> 1.5355482
B30: =A27 -> 2.5 | C30: SIF Inplane | D30: =0.9/(D29^0.666666) -> 3.0541029 | E30: =0.9/(E29^0.666666) -> 3.0541029 | F30: =0.9/(F29^0.666666) -> 2.3467987 | G30: =0.9/(G29^0.666666) -> 2.3467987 | I30: =0.9/(I29^0.666666) -> 1.6822451 | J30: =0.9/(J29^0.666666) -> 1.5867442 | K30: =0.9/(K29^0.666666) -> 1.5867442 | L30: =0.9/(L29^0.666666) -> 1.5867442 | N30: =0.9/(N29^0.666666) -> 1.2467648 | O30: =0.9/(O29^0.666666) -> 1.2467648 | P30: =0.9/(P29^0.666666) -> 1.2467648 | T30: =0.9/(T29^0.666666) -> 0.96454366 | U30: =0.9/(U29^0.666666) -> 0.67618728
A31: 3 | B31: =A31*25.4*1.5 -> 114.3 | C31: 88.9 | D31: 2.11 | E31: 2.11 | F31: 3.05 | G31: 3.05 | I31: 4.78 | J31: 5.49 | K31: 5.49 | L31: 5.49 | N31: 7.62 | O31: 7.62 | P31: 7.62 | T31: 11.13 | U31: 15.24
B32: =B31 -> 114.3 | C32: r mean | D32: =($C31/2)-(D31/2) -> 43.395 | E32: =($C31/2)-(E31/2) -> 43.395 | F32: =($C31/2)-(F31/2) -> 42.925 | G32: =($C31/2)-(G31/2) -> 42.925 | I32: =($C31/2)-(I31/2) -> 42.06 | J32: =($C31/2)-(J31/2) -> 41.705 | K32: =($C31/2)-(K31/2) -> 41.705 | L32: =($C31/2)-(L31/2) -> 41.705 | N32: =($C31/2)-(N31/2) -> 40.64 | O32: =($C31/2)-(O31/2) -> 40.64 | P32: =($C31/2)-(P31/2) -> 40.64 | T32: =($C31/2)-(T31/2) -> 38.885 | U32: =($C31/2)-(U31/2) -> 36.83
B33: =B31 -> 114.3 | C33: h ( for long radius bend) | D33: =D31*$B33/D32/D32 -> 0.12807056 | E33: =E31*$B33/E32/E32 -> 0.12807056 | F33: =F31*$B33/F32/F32 -> 0.18920189 | G33: =G31*$B33/G32/G32 -> 0.18920189 | I33: =I31*$B33/I32/I32 -> 0.30884146 | J33: =J31*$B33/J32/J32 -> 0.36077989 | K33: =K31*$B33/K32/K32 -> 0.36077989 | L33: =L31*$B33/L32/L32 -> 0.36077989 | N33: =N31*$B33/N32/N32 -> 0.52734375 | O33: =O31*$B33/O32/O32 -> 0.52734375 | P33: =P31*$B33/P32/P32 -> 0.52734375 | T33: =T31*$B33/T32/T32 -> 0.84135095 | U33: =U31*$B33/U32/U32 -> 1.2841855
B34: =A31 -> 3 | C34: SIF Inplane | D34: =0.9/(D33^0.666666) -> 3.5422215 | E34: =0.9/(E33^0.666666) -> 3.5422215 | F34: =0.9/(F33^0.666666) -> 2.7308115 | G34: =0.9/(G33^0.666666) -> 2.7308115 | I34: =0.9/(I33^0.666666) -> 1.9697833 | J34: =0.9/(J33^0.666666) -> 1.7758816 | K34: =0.9/(K33^0.666666) -> 1.7758816 | L34: =0.9/(L33^0.666666) -> 1.7758816 | N34: =0.9/(N33^0.666666) -> 1.3788376 | O34: =0.9/(O33^0.666666) -> 1.3788376 | P34: =0.9/(P33^0.666666) -> 1.3788376 | T34: =0.9/(T33^0.666666) -> 1.0098519 | U34: =0.9/(U33^0.666666) -> 0.76177037
A35: 4 | B35: =A35*25.4*1.5 -> 152.4 | C35: 114.3 | D35: 2.11 | E35: 2.11 | F35: 3.05 | G35: 3.05 | I35: 4.78 | J35: 6.02 | K35: 6.02 | L35: 6.02 | N35: 8.56 | O35: 8.56 | P35: 8.56 | T35: 13.49 | U35: 17.12
B36: =B35 -> 152.4 | C36: r mean | D36: =($C35/2)-(D35/2) -> 56.095 | E36: =($C35/2)-(E35/2) -> 56.095 | F36: =($C35/2)-(F35/2) -> 55.625 | G36: =($C35/2)-(G35/2) -> 55.625 | I36: =($C35/2)-(I35/2) -> 54.76 | J36: =($C35/2)-(J35/2) -> 54.14 | K36: =($C35/2)-(K35/2) -> 54.14 | L36: =($C35/2)-(L35/2) -> 54.14 | N36: =($C35/2)-(N35/2) -> 52.87 | O36: =($C35/2)-(O35/2) -> 52.87 | P36: =($C35/2)-(P35/2) -> 52.87 | T36: =($C35/2)-(T35/2) -> 50.405 | U36: =($C35/2)-(U35/2) -> 48.59
B37: =B35 -> 152.4 | C37: h ( for long radius bend) | D37: =D35*$B37/D36/D36 -> 0.10219252 | E37: =E35*$B37/E36/E36 -> 0.10219252 | F37: =F35*$B37/F36/F36 -> 0.15022588 | G37: =G35*$B37/G36/G36 -> 0.15022588 | I37: =I35*$B37/I36/I36 -> 0.2429327 | J37: =J35*$B37/J36/J36 -> 0.31300045 | K37: =K35*$B37/K36/K36 -> 0.31300045 | L37: =L35*$B37/L36/L36 -> 0.31300045 | N37: =N35*$B37/N36/N36 -> 0.46670248 | O37: =O35*$B37/O36/O36 -> 0.46670248 | P37: =P35*$B37/P36/P36 -> 0.46670248 | T37: =T35*$B37/T36/T36 -> 0.80918846 | U37: =U35*$B37/U36/U36 -> 1.1050831
B38: =A35 -> 4 | C38: SIF Inplane | D38: =0.9/(D37^0.666666) -> 4.1174573 | E38: =0.9/(E37^0.666666) -> 4.1174573 | F38: =0.9/(F37^0.666666) -> 3.1847752 | G38: =0.9/(G37^0.666666) -> 3.1847752 | I38: =0.9/(I37^0.666666) -> 2.3116289 | J38: =0.9/(J37^0.666666) -> 1.9522954 | K38: =0.9/(K37^0.666666) -> 1.9522954 | L38: =0.9/(L37^0.666666) -> 1.9522954 | N38: =0.9/(N37^0.666666) -> 1.4958299 | O38: =0.9/(O37^0.666666) -> 1.4958299 | P38: =0.9/(P37^0.666666) -> 1.4958299 | T38: =0.9/(T37^0.666666) -> 1.0364364 | U38: =0.9/(U37^0.666666) -> 0.84200096
A39: 6 | B39: =A39*25.4*1.5 -> 228.6 | C39: 168.3 | D39: 2.77 | E39: 2.77 | F39: 3.4 | G39: 3.4 | J39: 7.11 | K39: 7.11 | L39: 7.11 | N39: 10.97 | O39: 10.97 | P39: 10.97 | T39: 18.26 | U39: 21.95
B40: =B39 -> 228.6 | C40: r mean | D40: =($C39/2)-(D39/2) -> 82.765 | E40: =($C39/2)-(E39/2) -> 82.765 | F40: =($C39/2)-(F39/2) -> 82.45 | G40: =($C39/2)-(G39/2) -> 82.45 | J40: =($C39/2)-(J39/2) -> 80.595 | K40: =($C39/2)-(K39/2) -> 80.595 | L40: =($C39/2)-(L39/2) -> 80.595 | N40: =($C39/2)-(N39/2) -> 78.665 | O40: =($C39/2)-(O39/2) -> 78.665 | P40: =($C39/2)-(P39/2) -> 78.665 | T40: =($C39/2)-(T39/2) -> 75.02 | U40: =($C39/2)-(U39/2) -> 73.175
B41: =B39 -> 228.6 | C41: h ( for long radius bend) | D41: =D39*$B41/D40/D40 -> 0.092440558 | E41: =E39*$B41/E40/E40 -> 0.092440558 | F41: =F39*$B41/F40/F40 -> 0.11433359 | G41: =G39*$B41/G40/G40 -> 0.11433359 | J41: =J39*$B41/J40/J40 -> 0.25022438 | K41: =K39*$B41/K40/K40 -> 0.25022438 | L41: =L39*$B41/L40/L40 -> 0.25022438 | N41: =N39*$B41/N40/N40 -> 0.40524695 | O41: =O39*$B41/O40/O40 -> 0.40524695 | P41: =P39*$B41/P40/P40 -> 0.40524695 | T41: =T39*$B41/T40/T40 -> 0.74169078 | U41: =U39*$B41/U40/U40 -> 0.9370986
B42: =A39 -> 6 | C42: SIF Inplane | D42: =0.9/(D41^0.666666) -> 4.4021697 | E42: =0.9/(E41^0.666666) -> 4.4021697 | F42: =0.9/(F41^0.666666) -> 3.820551 | G42: =0.9/(G41^0.666666) -> 3.820551 | J42: =0.9/(J41^0.666666) -> 2.2664998 | K42: =0.9/(K41^0.666666) -> 2.2664998 | L42: =0.9/(L41^0.666666) -> 2.2664998 | N42: =0.9/(N41^0.666666) -> 1.6434724 | O42: =0.9/(O41^0.666666) -> 1.6434724 | P42: =0.9/(P41^0.666666) -> 1.6434724 | T42: =0.9/(T41^0.666666) -> 1.0983999 | U42: =0.9/(U41^0.666666) -> 0.93983648
...
