Workbook

Sheet Master
G2: Leg 2
F3: Leg 1 | G3: Feet | H3: 2 | I3: 2.5 | J3: =I3+0.5 -> 3 | K3: =J3+0.5 -> 3.5 | L3: =K3+0.5 -> 4 | M3: =L3+0.5 -> 4.5 | N3: =M3+0.5 -> 5 | O3: =N3+0.5 -> 5.5 | P3: =O3+0.5 -> 6 | Q3: =P3+0.5 -> 6.5 | ... AB3: =AA3+0.5 -> 12 | AC3: =AB3+1 -> 13 | AD3: =AC3+1 -> 14 | AE3: =AD3+1 -> 15 | AF3: =AE3+1 -> 16 | AG3: =AF3+1 -> 17 | AH3: =AG3+1 -> 18 | AI3: =AH3+1 -> 19 | AJ3: =AI3+1 -> 20 | ... BD3: =BC3+1 -> 40
G4: 2 | H4: =IF( (MAX(H$3,$G4)*$C$16)<(48*(MIN(H$3,$G4))^2*$C$15/$C$14/$C$13),"Pass","Fail") -> Fail | I4: =IF( (MAX(I$3,$G4)*$C$16)<(48*(MIN(I$3,$G4))^2*$C$15/$C$14/$C$13),"Pass","Fail") -> Fail | J4: =IF( (MAX(J$3,$G4)*$C$16)<(48*(MIN(J$3,$G4))^2*$C$15/$C$14/$C$13),"Pass","Fail") -> Fail | K4: =IF( (MAX(K$3,$G4)*$C$16)<(48*(MIN(K$3,$G4))^2*$C$15/$C$14/$C$13),"Pass","Fail") -> Fail | L4: =IF( (MAX(L$3,$G4)*$C$16)<(48*(MIN(L$3,$G4))^2*$C$15/$C$14/$C$13),"Pass","Fail") -> Fail | M4: =IF( (MAX(M$3,$G4)*$C$16)<(48*(MIN(M$3,$G4))^2*$C$15/$C$14/$C$13),"Pass","Fail") -> Fail | N4: =IF( (MAX(N$3,$G4)*$C$16)<(48*(MIN(N$3,$G4))^2*$C$15/$C$14/$C$13),"Pass","Fail") -> Fail | O4: =IF( (MAX(O$3,$G4)*$C$16)<(48*(MIN(O$3,$G4))^2*$C$15/$C$14/$C$13),"Pass","Fail") -> Fail | ... BD4: =IF( (MAX(BD$3,$G4)*$C$16)<(48*(MIN(BD$3,$G4))^2*$C$15/$C$14/$C$13),"Pass","Fail") -> Fail
G5: 2.5 | H5: =IF( (MAX(H$3,$G5)*$C$16)<(48*(MIN(H$3,$G5))^2*$C$15/$C$14/$C$13),"Pass","Fail") -> Fail | I5: =IF( (MAX(I$3,$G5)*$C$16)<(48*(MIN(I$3,$G5))^2*$C$15/$C$14/$C$13),"Pass","Fail") -> Fail | J5: =IF( (MAX(J$3,$G5)*$C$16)<(48*(MIN(J$3,$G5))^2*$C$15/$C$14/$C$13),"Pass","Fail") -> Fail | K5: =IF( (MAX(K$3,$G5)*$C$16)<(48*(MIN(K$3,$G5))^2*$C$15/$C$14/$C$13),"Pass","Fail") -> Fail | L5: =IF( (MAX(L$3,$G5)*$C$16)<(48*(MIN(L$3,$G5))^2*$C$15/$C$14/$C$13),"Pass","Fail") -> Fail | M5: =IF( (MAX(M$3,$G5)*$C$16)<(48*(MIN(M$3,$G5))^2*$C$15/$C$14/$C$13),"Pass","Fail") -> Fail | N5: =IF( (MAX(N$3,$G5)*$C$16)<(48*(MIN(N$3,$G5))^2*$C$15/$C$14/$C$13),"Pass","Fail") -> Fail | O5: =IF( (MAX(O$3,$G5)*$C$16)<(48*(MIN(O$3,$G5))^2*$C$15/$C$14/$C$13),"Pass","Fail") -> Fail | ... BD5: =IF( (MAX(BD$3,$G5)*$C$16)<(48*(MIN(BD$3,$G5))^2*$C$15/$C$14/$C$13),"Pass","Fail") -> Fail
B6: Guided Cantilver Check | G6: =G5+0.5 -> 3 | H6: =IF( (MAX(H$3,$G6)*$C$16)<(48*(MIN(H$3,$G6))^2*$C$15/$C$14/$C$13),"Pass","Fail") -> Fail | I6: =IF( (MAX(I$3,$G6)*$C$16)<(48*(MIN(I$3,$G6))^2*$C$15/$C$14/$C$13),"Pass","Fail") -> Fail | J6: =IF( (MAX(J$3,$G6)*$C$16)<(48*(MIN(J$3,$G6))^2*$C$15/$C$14/$C$13),"Pass","Fail") -> Fail | K6: =IF( (MAX(K$3,$G6)*$C$16)<(48*(MIN(K$3,$G6))^2*$C$15/$C$14/$C$13),"Pass","Fail") -> Fail | L6: =IF( (MAX(L$3,$G6)*$C$16)<(48*(MIN(L$3,$G6))^2*$C$15/$C$14/$C$13),"Pass","Fail") -> Fail | M6: =IF( (MAX(M$3,$G6)*$C$16)<(48*(MIN(M$3,$G6))^2*$C$15/$C$14/$C$13),"Pass","Fail") -> Fail | N6: =IF( (MAX(N$3,$G6)*$C$16)<(48*(MIN(N$3,$G6))^2*$C$15/$C$14/$C$13),"Pass","Fail") -> Fail | O6: =IF( (MAX(O$3,$G6)*$C$16)<(48*(MIN(O$3,$G6))^2*$C$15/$C$14/$C$13),"Pass","Fail") -> Fail | ... BD6: =IF( (MAX(BD$3,$G6)*$C$16)<(48*(MIN(BD$3,$G6))^2*$C$15/$C$14/$C$13),"Pass","Fail") -> Fail
B7: Single Plane - 2 member Square leg configuration | G7: =G6+0.5 -> 3.5 | H7: =IF( (MAX(H$3,$G7)*$C$16)<(48*(MIN(H$3,$G7))^2*$C$15/$C$14/$C$13),"Pass","Fail") -> Fail | I7: =IF( (MAX(I$3,$G7)*$C$16)<(48*(MIN(I$3,$G7))^2*$C$15/$C$14/$C$13),"Pass","Fail") -> Fail | J7: =IF( (MAX(J$3,$G7)*$C$16)<(48*(MIN(J$3,$G7))^2*$C$15/$C$14/$C$13),"Pass","Fail") -> Fail | K7: =IF( (MAX(K$3,$G7)*$C$16)<(48*(MIN(K$3,$G7))^2*$C$15/$C$14/$C$13),"Pass","Fail") -> Fail | L7: =IF( (MAX(L$3,$G7)*$C$16)<(48*(MIN(L$3,$G7))^2*$C$15/$C$14/$C$13),"Pass","Fail") -> Fail | M7: =IF( (MAX(M$3,$G7)*$C$16)<(48*(MIN(M$3,$G7))^2*$C$15/$C$14/$C$13),"Pass","Fail") -> Fail | N7: =IF( (MAX(N$3,$G7)*$C$16)<(48*(MIN(N$3,$G7))^2*$C$15/$C$14/$C$13),"Pass","Fail") -> Fail | O7: =IF( (MAX(O$3,$G7)*$C$16)<(48*(MIN(O$3,$G7))^2*$C$15/$C$14/$C$13),"Pass","Fail") -> Fail | ... BD7: =IF( (MAX(BD$3,$G7)*$C$16)<(48*(MIN(BD$3,$G7))^2*$C$15/$C$14/$C$13),"Pass","Fail") -> Fail
G8: =G7+0.5 -> 4 | H8: =IF( (MAX(H$3,$G8)*$C$16)<(48*(MIN(H$3,$G8))^2*$C$15/$C$14/$C$13),"Pass","Fail") -> Fail | I8: =IF( (MAX(I$3,$G8)*$C$16)<(48*(MIN(I$3,$G8))^2*$C$15/$C$14/$C$13),"Pass","Fail") -> Fail | J8: =IF( (MAX(J$3,$G8)*$C$16)<(48*(MIN(J$3,$G8))^2*$C$15/$C$14/$C$13),"Pass","Fail") -> Fail | K8: =IF( (MAX(K$3,$G8)*$C$16)<(48*(MIN(K$3,$G8))^2*$C$15/$C$14/$C$13),"Pass","Fail") -> Fail | L8: =IF( (MAX(L$3,$G8)*$C$16)<(48*(MIN(L$3,$G8))^2*$C$15/$C$14/$C$13),"Pass","Fail") -> Pass | M8: =IF( (MAX(M$3,$G8)*$C$16)<(48*(MIN(M$3,$G8))^2*$C$15/$C$14/$C$13),"Pass","Fail") -> Pass | N8: =IF( (MAX(N$3,$G8)*$C$16)<(48*(MIN(N$3,$G8))^2*$C$15/$C$14/$C$13),"Pass","Fail") -> Fail | O8: =IF( (MAX(O$3,$G8)*$C$16)<(48*(MIN(O$3,$G8))^2*$C$15/$C$14/$C$13),"Pass","Fail") -> Fail | ... BD8: =IF( (MAX(BD$3,$G8)*$C$16)<(48*(MIN(BD$3,$G8))^2*$C$15/$C$14/$C$13),"Pass","Fail") -> Fail
B9: Simple Check | G9: =G8+0.5 -> 4.5 | H9: =IF( (MAX(H$3,$G9)*$C$16)<(48*(MIN(H$3,$G9))^2*$C$15/$C$14/$C$13),"Pass","Fail") -> Fail | I9: =IF( (MAX(I$3,$G9)*$C$16)<(48*(MIN(I$3,$G9))^2*$C$15/$C$14/$C$13),"Pass","Fail") -> Fail | J9: =IF( (MAX(J$3,$G9)*$C$16)<(48*(MIN(J$3,$G9))^2*$C$15/$C$14/$C$13),"Pass","Fail") -> Fail | K9: =IF( (MAX(K$3,$G9)*$C$16)<(48*(MIN(K$3,$G9))^2*$C$15/$C$14/$C$13),"Pass","Fail") -> Fail | L9: =IF( (MAX(L$3,$G9)*$C$16)<(48*(MIN(L$3,$G9))^2*$C$15/$C$14/$C$13),"Pass","Fail") -> Pass | M9: =IF( (MAX(M$3,$G9)*$C$16)<(48*(MIN(M$3,$G9))^2*$C$15/$C$14/$C$13),"Pass","Fail") -> Pass | N9: =IF( (MAX(N$3,$G9)*$C$16)<(48*(MIN(N$3,$G9))^2*$C$15/$C$14/$C$13),"Pass","Fail") -> Pass | O9: =IF( (MAX(O$3,$G9)*$C$16)<(48*(MIN(O$3,$G9))^2*$C$15/$C$14/$C$13),"Pass","Fail") -> Pass | ... BD9: =IF( (MAX(BD$3,$G9)*$C$16)<(48*(MIN(BD$3,$G9))^2*$C$15/$C$14/$C$13),"Pass","Fail") -> Fail
B10: D, Pipe Dia | C10: 4" - 100 | D10: in | G10: =G9+0.5 -> 5 | H10: =IF( (MAX(H$3,$G10)*$C$16)<(48*(MIN(H$3,$G10))^2*$C$15/$C$14/$C$13),"Pass","Fail") -> Fail | I10: =IF( (MAX(I$3,$G10)*$C$16)<(48*(MIN(I$3,$G10))^2*$C$15/$C$14/$C$13),"Pass","Fail") -> Fail | J10: =IF( (MAX(J$3,$G10)*$C$16)<(48*(MIN(J$3,$G10))^2*$C$15/$C$14/$C$13),"Pass","Fail") -> Fail | K10: =IF( (MAX(K$3,$G10)*$C$16)<(48*(MIN(K$3,$G10))^2*$C$15/$C$14/$C$13),"Pass","Fail") -> Fail | L10: =IF( (MAX(L$3,$G10)*$C$16)<(48*(MIN(L$3,$G10))^2*$C$15/$C$14/$C$13),"Pass","Fail") -> Fail | M10: =IF( (MAX(M$3,$G10)*$C$16)<(48*(MIN(M$3,$G10))^2*$C$15/$C$14/$C$13),"Pass","Fail") -> Pass | N10: =IF( (MAX(N$3,$G10)*$C$16)<(48*(MIN(N$3,$G10))^2*$C$15/$C$14/$C$13),"Pass","Fail") -> Pass | O10: =IF( (MAX(O$3,$G10)*$C$16)<(48*(MIN(O$3,$G10))^2*$C$15/$C$14/$C$13),"Pass","Fail") -> Pass | ... BD10: =IF( (MAX(BD$3,$G10)*$C$16)<(48*(MIN(BD$3,$G10))^2*$C$15/$C$14/$C$13),"Pass","Fail") -> Fail
B11: Select Material | C11: Austenitic Stainless Steels 18Cr-8Ni | G11: =G10+0.5 -> 5.5 | H11: =IF( (MAX(H$3,$G11)*$C$16)<(48*(MIN(H$3,$G11))^2*$C$15/$C$14/$C$13),"Pass","Fail") -> Fail | I11: =IF( (MAX(I$3,$G11)*$C$16)<(48*(MIN(I$3,$G11))^2*$C$15/$C$14/$C$13),"Pass","Fail") -> Fail | J11: =IF( (MAX(J$3,$G11)*$C$16)<(48*(MIN(J$3,$G11))^2*$C$15/$C$14/$C$13),"Pass","Fail") -> Fail | K11: =IF( (MAX(K$3,$G11)*$C$16)<(48*(MIN(K$3,$G11))^2*$C$15/$C$14/$C$13),"Pass","Fail") -> Fail | L11: =IF( (MAX(L$3,$G11)*$C$16)<(48*(MIN(L$3,$G11))^2*$C$15/$C$14/$C$13),"Pass","Fail") -> Fail | M11: =IF( (MAX(M$3,$G11)*$C$16)<(48*(MIN(M$3,$G11))^2*$C$15/$C$14/$C$13),"Pass","Fail") -> Pass | N11: =IF( (MAX(N$3,$G11)*$C$16)<(48*(MIN(N$3,$G11))^2*$C$15/$C$14/$C$13),"Pass","Fail") -> Pass | O11: =IF( (MAX(O$3,$G11)*$C$16)<(48*(MIN(O$3,$G11))^2*$C$15/$C$14/$C$13),"Pass","Fail") -> Pass | ... BD11: =IF( (MAX(BD$3,$G11)*$C$16)<(48*(MIN(BD$3,$G11))^2*$C$15/$C$14/$C$13),"Pass","Fail") -> Fail
B12: Temperature | C12: 400 | D12: Deg F | G12: =G11+0.5 -> 6 | H12: =IF( (MAX(H$3,$G12)*$C$16)<(48*(MIN(H$3,$G12))^2*$C$15/$C$14/$C$13),"Pass","Fail") -> Fail | I12: =IF( (MAX(I$3,$G12)*$C$16)<(48*(MIN(I$3,$G12))^2*$C$15/$C$14/$C$13),"Pass","Fail") -> Fail | J12: =IF( (MAX(J$3,$G12)*$C$16)<(48*(MIN(J$3,$G12))^2*$C$15/$C$14/$C$13),"Pass","Fail") -> Fail | K12: =IF( (MAX(K$3,$G12)*$C$16)<(48*(MIN(K$3,$G12))^2*$C$15/$C$14/$C$13),"Pass","Fail") -> Fail | L12: =IF( (MAX(L$3,$G12)*$C$16)<(48*(MIN(L$3,$G12))^2*$C$15/$C$14/$C$13),"Pass","Fail") -> Fail | M12: =IF( (MAX(M$3,$G12)*$C$16)<(48*(MIN(M$3,$G12))^2*$C$15/$C$14/$C$13),"Pass","Fail") -> Fail | N12: =IF( (MAX(N$3,$G12)*$C$16)<(48*(MIN(N$3,$G12))^2*$C$15/$C$14/$C$13),"Pass","Fail") -> Pass | O12: =IF( (MAX(O$3,$G12)*$C$16)<(48*(MIN(O$3,$G12))^2*$C$15/$C$14/$C$13),"Pass","Fail") -> Pass | ... BD12: =IF( (MAX(BD$3,$G12)*$C$16)<(48*(MIN(BD$3,$G12))^2*$C$15/$C$14/$C$13),"Pass","Fail") -> Fail
B13: OD of pipe | C13: =VLOOKUP(C10,'Diameter data'!B11:C53,2,FALSE)/25.4 -> 4.5 | D13: in | G13: =G12+0.5 -> 6.5 | H13: =IF( (MAX(H$3,$G13)*$C$16)<(48*(MIN(H$3,$G13))^2*$C$15/$C$14/$C$13),"Pass","Fail") -> Fail | I13: =IF( (MAX(I$3,$G13)*$C$16)<(48*(MIN(I$3,$G13))^2*$C$15/$C$14/$C$13),"Pass","Fail") -> Fail | J13: =IF( (MAX(J$3,$G13)*$C$16)<(48*(MIN(J$3,$G13))^2*$C$15/$C$14/$C$13),"Pass","Fail") -> Fail | K13: =IF( (MAX(K$3,$G13)*$C$16)<(48*(MIN(K$3,$G13))^2*$C$15/$C$14/$C$13),"Pass","Fail") -> Fail | L13: =IF( (MAX(L$3,$G13)*$C$16)<(48*(MIN(L$3,$G13))^2*$C$15/$C$14/$C$13),"Pass","Fail") -> Fail | M13: =IF( (MAX(M$3,$G13)*$C$16)<(48*(MIN(M$3,$G13))^2*$C$15/$C$14/$C$13),"Pass","Fail") -> Fail | N13: =IF( (MAX(N$3,$G13)*$C$16)<(48*(MIN(N$3,$G13))^2*$C$15/$C$14/$C$13),"Pass","Fail") -> Pass | O13: =IF( (MAX(O$3,$G13)*$C$16)<(48*(MIN(O$3,$G13))^2*$C$15/$C$14/$C$13),"Pass","Fail") -> Pass | ... BD13: =IF( (MAX(BD$3,$G13)*$C$16)<(48*(MIN(BD$3,$G13))^2*$C$15/$C$14/$C$13),"Pass","Fail") -> Fail
B14: E, Elastic Modulus | C14: 29500000 | D14: psi | G14: =G13+0.5 -> 7 | H14: =IF( (MAX(H$3,$G14)*$C$16)<(48*(MIN(H$3,$G14))^2*$C$15/$C$14/$C$13),"Pass","Fail") -> Fail | I14: =IF( (MAX(I$3,$G14)*$C$16)<(48*(MIN(I$3,$G14))^2*$C$15/$C$14/$C$13),"Pass","Fail") -> Fail | J14: =IF( (MAX(J$3,$G14)*$C$16)<(48*(MIN(J$3,$G14))^2*$C$15/$C$14/$C$13),"Pass","Fail") -> Fail | K14: =IF( (MAX(K$3,$G14)*$C$16)<(48*(MIN(K$3,$G14))^2*$C$15/$C$14/$C$13),"Pass","Fail") -> Fail | L14: =IF( (MAX(L$3,$G14)*$C$16)<(48*(MIN(L$3,$G14))^2*$C$15/$C$14/$C$13),"Pass","Fail") -> Fail | M14: =IF( (MAX(M$3,$G14)*$C$16)<(48*(MIN(M$3,$G14))^2*$C$15/$C$14/$C$13),"Pass","Fail") -> Fail | N14: =IF( (MAX(N$3,$G14)*$C$16)<(48*(MIN(N$3,$G14))^2*$C$15/$C$14/$C$13),"Pass","Fail") -> Pass | O14: =IF( (MAX(O$3,$G14)*$C$16)<(48*(MIN(O$3,$G14))^2*$C$15/$C$14/$C$13),"Pass","Fail") -> Pass | ... BD14: =IF( (MAX(BD$3,$G14)*$C$16)<(48*(MIN(BD$3,$G14))^2*$C$15/$C$14/$C$13),"Pass","Fail") -> Fail
B15: Sa, Allowable Stress | C15: 30000 | D15: psi | G15: =G14+0.5 -> 7.5 | H15: =IF( (MAX(H$3,$G15)*$C$16)<(48*(MIN(H$3,$G15))^2*$C$15/$C$14/$C$13),"Pass","Fail") -> Fail | I15: =IF( (MAX(I$3,$G15)*$C$16)<(48*(MIN(I$3,$G15))^2*$C$15/$C$14/$C$13),"Pass","Fail") -> Fail | J15: =IF( (MAX(J$3,$G15)*$C$16)<(48*(MIN(J$3,$G15))^2*$C$15/$C$14/$C$13),"Pass","Fail") -> Fail | K15: =IF( (MAX(K$3,$G15)*$C$16)<(48*(MIN(K$3,$G15))^2*$C$15/$C$14/$C$13),"Pass","Fail") -> Fail | L15: =IF( (MAX(L$3,$G15)*$C$16)<(48*(MIN(L$3,$G15))^2*$C$15/$C$14/$C$13),"Pass","Fail") -> Fail | M15: =IF( (MAX(M$3,$G15)*$C$16)<(48*(MIN(M$3,$G15))^2*$C$15/$C$14/$C$13),"Pass","Fail") -> Fail | N15: =IF( (MAX(N$3,$G15)*$C$16)<(48*(MIN(N$3,$G15))^2*$C$15/$C$14/$C$13),"Pass","Fail") -> Fail | O15: =IF( (MAX(O$3,$G15)*$C$16)<(48*(MIN(O$3,$G15))^2*$C$15/$C$14/$C$13),"Pass","Fail") -> Pass | ... BD15: =IF( (MAX(BD$3,$G15)*$C$16)<(48*(MIN(BD$3,$G15))^2*$C$15/$C$14/$C$13),"Pass","Fail") -> Fail
B16: Thermal coefficent of Expansion | C16: ='Diameter data'!J3/100 -> 0.038 | D16: in/ft | G16: =G15+0.5 -> 8 | H16: =IF( (MAX(H$3,$G16)*$C$16)<(48*(MIN(H$3,$G16))^2*$C$15/$C$14/$C$13),"Pass","Fail") -> Fail | I16: =IF( (MAX(I$3,$G16)*$C$16)<(48*(MIN(I$3,$G16))^2*$C$15/$C$14/$C$13),"Pass","Fail") -> Fail | J16: =IF( (MAX(J$3,$G16)*$C$16)<(48*(MIN(J$3,$G16))^2*$C$15/$C$14/$C$13),"Pass","Fail") -> Fail | K16: =IF( (MAX(K$3,$G16)*$C$16)<(48*(MIN(K$3,$G16))^2*$C$15/$C$14/$C$13),"Pass","Fail") -> Fail | L16: =IF( (MAX(L$3,$G16)*$C$16)<(48*(MIN(L$3,$G16))^2*$C$15/$C$14/$C$13),"Pass","Fail") -> Fail | M16: =IF( (MAX(M$3,$G16)*$C$16)<(48*(MIN(M$3,$G16))^2*$C$15/$C$14/$C$13),"Pass","Fail") -> Fail | N16: =IF( (MAX(N$3,$G16)*$C$16)<(48*(MIN(N$3,$G16))^2*$C$15/$C$14/$C$13),"Pass","Fail") -> Fail | O16: =IF( (MAX(O$3,$G16)*$C$16)<(48*(MIN(O$3,$G16))^2*$C$15/$C$14/$C$13),"Pass","Fail") -> Pass | ... BD16: =IF( (MAX(BD$3,$G16)*$C$16)<(48*(MIN(BD$3,$G16))^2*$C$15/$C$14/$C$13),"Pass","Fail") -> Fail
G17: =G16+0.5 -> 8.5 | H17: =IF( (MAX(H$3,$G17)*$C$16)<(48*(MIN(H$3,$G17))^2*$C$15/$C$14/$C$13),"Pass","Fail") -> Fail | I17: =IF( (MAX(I$3,$G17)*$C$16)<(48*(MIN(I$3,$G17))^2*$C$15/$C$14/$C$13),"Pass","Fail") -> Fail | J17: =IF( (MAX(J$3,$G17)*$C$16)<(48*(MIN(J$3,$G17))^2*$C$15/$C$14/$C$13),"Pass","Fail") -> Fail | K17: =IF( (MAX(K$3,$G17)*$C$16)<(48*(MIN(K$3,$G17))^2*$C$15/$C$14/$C$13),"Pass","Fail") -> Fail | L17: =IF( (MAX(L$3,$G17)*$C$16)<(48*(MIN(L$3,$G17))^2*$C$15/$C$14/$C$13),"Pass","Fail") -> Fail | M17: =IF( (MAX(M$3,$G17)*$C$16)<(48*(MIN(M$3,$G17))^2*$C$15/$C$14/$C$13),"Pass","Fail") -> Fail | N17: =IF( (MAX(N$3,$G17)*$C$16)<(48*(MIN(N$3,$G17))^2*$C$15/$C$14/$C$13),"Pass","Fail") -> Fail | O17: =IF( (MAX(O$3,$G17)*$C$16)<(48*(MIN(O$3,$G17))^2*$C$15/$C$14/$C$13),"Pass","Fail") -> Pass | ... BD17: =IF( (MAX(BD$3,$G17)*$C$16)<(48*(MIN(BD$3,$G17))^2*$C$15/$C$14/$C$13),"Pass","Fail") -> Fail
G18: =G17+0.5 -> 9 | H18: =IF( (MAX(H$3,$G18)*$C$16)<(48*(MIN(H$3,$G18))^2*$C$15/$C$14/$C$13),"Pass","Fail") -> Fail | I18: =IF( (MAX(I$3,$G18)*$C$16)<(48*(MIN(I$3,$G18))^2*$C$15/$C$14/$C$13),"Pass","Fail") -> Fail | J18: =IF( (MAX(J$3,$G18)*$C$16)<(48*(MIN(J$3,$G18))^2*$C$15/$C$14/$C$13),"Pass","Fail") -> Fail | K18: =IF( (MAX(K$3,$G18)*$C$16)<(48*(MIN(K$3,$G18))^2*$C$15/$C$14/$C$13),"Pass","Fail") -> Fail | L18: =IF( (MAX(L$3,$G18)*$C$16)<(48*(MIN(L$3,$G18))^2*$C$15/$C$14/$C$13),"Pass","Fail") -> Fail | M18: =IF( (MAX(M$3,$G18)*$C$16)<(48*(MIN(M$3,$G18))^2*$C$15/$C$14/$C$13),"Pass","Fail") -> Fail | N18: =IF( (MAX(N$3,$G18)*$C$16)<(48*(MIN(N$3,$G18))^2*$C$15/$C$14/$C$13),"Pass","Fail") -> Fail | O18: =IF( (MAX(O$3,$G18)*$C$16)<(48*(MIN(O$3,$G18))^2*$C$15/$C$14/$C$13),"Pass","Fail") -> Fail | ... BD18: =IF( (MAX(BD$3,$G18)*$C$16)<(48*(MIN(BD$3,$G18))^2*$C$15/$C$14/$C$13),"Pass","Fail") -> Fail
B19: Advanced | G19: =G18+0.5 -> 9.5 | H19: =IF( (MAX(H$3,$G19)*$C$16)<(48*(MIN(H$3,$G19))^2*$C$15/$C$14/$C$13),"Pass","Fail") -> Fail | I19: =IF( (MAX(I$3,$G19)*$C$16)<(48*(MIN(I$3,$G19))^2*$C$15/$C$14/$C$13),"Pass","Fail") -> Fail | J19: =IF( (MAX(J$3,$G19)*$C$16)<(48*(MIN(J$3,$G19))^2*$C$15/$C$14/$C$13),"Pass","Fail") -> Fail | K19: =IF( (MAX(K$3,$G19)*$C$16)<(48*(MIN(K$3,$G19))^2*$C$15/$C$14/$C$13),"Pass","Fail") -> Fail | L19: =IF( (MAX(L$3,$G19)*$C$16)<(48*(MIN(L$3,$G19))^2*$C$15/$C$14/$C$13),"Pass","Fail") -> Fail | M19: =IF( (MAX(M$3,$G19)*$C$16)<(48*(MIN(M$3,$G19))^2*$C$15/$C$14/$C$13),"Pass","Fail") -> Fail | N19: =IF( (MAX(N$3,$G19)*$C$16)<(48*(MIN(N$3,$G19))^2*$C$15/$C$14/$C$13),"Pass","Fail") -> Fail | O19: =IF( (MAX(O$3,$G19)*$C$16)<(48*(MIN(O$3,$G19))^2*$C$15/$C$14/$C$13),"Pass","Fail") -> Fail | ... BD19: =IF( (MAX(BD$3,$G19)*$C$16)<(48*(MIN(BD$3,$G19))^2*$C$15/$C$14/$C$13),"Pass","Fail") -> Fail
B20: L, Length of Pipe | C20: 11 | D20: ft | G20: =G19+0.5 -> 10 | H20: =IF( (MAX(H$3,$G20)*$C$16)<(48*(MIN(H$3,$G20))^2*$C$15/$C$14/$C$13),"Pass","Fail") -> Fail | I20: =IF( (MAX(I$3,$G20)*$C$16)<(48*(MIN(I$3,$G20))^2*$C$15/$C$14/$C$13),"Pass","Fail") -> Fail | J20: =IF( (MAX(J$3,$G20)*$C$16)<(48*(MIN(J$3,$G20))^2*$C$15/$C$14/$C$13),"Pass","Fail") -> Fail | K20: =IF( (MAX(K$3,$G20)*$C$16)<(48*(MIN(K$3,$G20))^2*$C$15/$C$14/$C$13),"Pass","Fail") -> Fail | L20: =IF( (MAX(L$3,$G20)*$C$16)<(48*(MIN(L$3,$G20))^2*$C$15/$C$14/$C$13),"Pass","Fail") -> Fail | M20: =IF( (MAX(M$3,$G20)*$C$16)<(48*(MIN(M$3,$G20))^2*$C$15/$C$14/$C$13),"Pass","Fail") -> Fail | N20: =IF( (MAX(N$3,$G20)*$C$16)<(48*(MIN(N$3,$G20))^2*$C$15/$C$14/$C$13),"Pass","Fail") -> Fail | O20: =IF( (MAX(O$3,$G20)*$C$16)<(48*(MIN(O$3,$G20))^2*$C$15/$C$14/$C$13),"Pass","Fail") -> Fail | ... BD20: =IF( (MAX(BD$3,$G20)*$C$16)<(48*(MIN(BD$3,$G20))^2*$C$15/$C$14/$C$13),"Pass","Fail") -> Fail
B21: dc, deflection thermal | C21: =C20*C16 -> 0.418 | D21: in | G21: =G20+0.5 -> 10.5 | H21: =IF( (MAX(H$3,$G21)*$C$16)<(48*(MIN(H$3,$G21))^2*$C$15/$C$14/$C$13),"Pass","Fail") -> Fail | I21: =IF( (MAX(I$3,$G21)*$C$16)<(48*(MIN(I$3,$G21))^2*$C$15/$C$14/$C$13),"Pass","Fail") -> Fail | J21: =IF( (MAX(J$3,$G21)*$C$16)<(48*(MIN(J$3,$G21))^2*$C$15/$C$14/$C$13),"Pass","Fail") -> Fail | K21: =IF( (MAX(K$3,$G21)*$C$16)<(48*(MIN(K$3,$G21))^2*$C$15/$C$14/$C$13),"Pass","Fail") -> Fail | L21: =IF( (MAX(L$3,$G21)*$C$16)<(48*(MIN(L$3,$G21))^2*$C$15/$C$14/$C$13),"Pass","Fail") -> Fail | M21: =IF( (MAX(M$3,$G21)*$C$16)<(48*(MIN(M$3,$G21))^2*$C$15/$C$14/$C$13),"Pass","Fail") -> Fail | N21: =IF( (MAX(N$3,$G21)*$C$16)<(48*(MIN(N$3,$G21))^2*$C$15/$C$14/$C$13),"Pass","Fail") -> Fail | O21: =IF( (MAX(O$3,$G21)*$C$16)<(48*(MIN(O$3,$G21))^2*$C$15/$C$14/$C$13),"Pass","Fail") -> Fail | ... BD21: =IF( (MAX(BD$3,$G21)*$C$16)<(48*(MIN(BD$3,$G21))^2*$C$15/$C$14/$C$13),"Pass","Fail") -> Fail
B22: d, allowable deflection | C22: =48*C20^2*C15/C14/C13 -> 1.3125424 | D22: in | G22: =G21+0.5 -> 11 | H22: =IF( (MAX(H$3,$G22)*$C$16)<(48*(MIN(H$3,$G22))^2*$C$15/$C$14/$C$13),"Pass","Fail") -> Fail | I22: =IF( (MAX(I$3,$G22)*$C$16)<(48*(MIN(I$3,$G22))^2*$C$15/$C$14/$C$13),"Pass","Fail") -> Fail | J22: =IF( (MAX(J$3,$G22)*$C$16)<(48*(MIN(J$3,$G22))^2*$C$15/$C$14/$C$13),"Pass","Fail") -> Fail | K22: =IF( (MAX(K$3,$G22)*$C$16)<(48*(MIN(K$3,$G22))^2*$C$15/$C$14/$C$13),"Pass","Fail") -> Fail | L22: =IF( (MAX(L$3,$G22)*$C$16)<(48*(MIN(L$3,$G22))^2*$C$15/$C$14/$C$13),"Pass","Fail") -> Fail | M22: =IF( (MAX(M$3,$G22)*$C$16)<(48*(MIN(M$3,$G22))^2*$C$15/$C$14/$C$13),"Pass","Fail") -> Fail | N22: =IF( (MAX(N$3,$G22)*$C$16)<(48*(MIN(N$3,$G22))^2*$C$15/$C$14/$C$13),"Pass","Fail") -> Fail | O22: =IF( (MAX(O$3,$G22)*$C$16)<(48*(MIN(O$3,$G22))^2*$C$15/$C$14/$C$13),"Pass","Fail") -> Fail | ... BD22: =IF( (MAX(BD$3,$G22)*$C$16)<(48*(MIN(BD$3,$G22))^2*$C$15/$C$14/$C$13),"Pass","Fail") -> Fail
B23: Status | C23: =IF(C21<C22,"Pass", "Fail") -> Pass | G23: =G22+0.5 -> 11.5 | H23: =IF( (MAX(H$3,$G23)*$C$16)<(48*(MIN(H$3,$G23))^2*$C$15/$C$14/$C$13),"Pass","Fail") -> Fail | I23: =IF( (MAX(I$3,$G23)*$C$16)<(48*(MIN(I$3,$G23))^2*$C$15/$C$14/$C$13),"Pass","Fail") -> Fail | J23: =IF( (MAX(J$3,$G23)*$C$16)<(48*(MIN(J$3,$G23))^2*$C$15/$C$14/$C$13),"Pass","Fail") -> Fail | K23: =IF( (MAX(K$3,$G23)*$C$16)<(48*(MIN(K$3,$G23))^2*$C$15/$C$14/$C$13),"Pass","Fail") -> Fail | L23: =IF( (MAX(L$3,$G23)*$C$16)<(48*(MIN(L$3,$G23))^2*$C$15/$C$14/$C$13),"Pass","Fail") -> Fail | M23: =IF( (MAX(M$3,$G23)*$C$16)<(48*(MIN(M$3,$G23))^2*$C$15/$C$14/$C$13),"Pass","Fail") -> Fail | N23: =IF( (MAX(N$3,$G23)*$C$16)<(48*(MIN(N$3,$G23))^2*$C$15/$C$14/$C$13),"Pass","Fail") -> Fail | O23: =IF( (MAX(O$3,$G23)*$C$16)<(48*(MIN(O$3,$G23))^2*$C$15/$C$14/$C$13),"Pass","Fail") -> Fail | ... BD23: =IF( (MAX(BD$3,$G23)*$C$16)<(48*(MIN(BD$3,$G23))^2*$C$15/$C$14/$C$13),"Pass","Fail") -> Fail
G24: =G23+0.5 -> 12 | H24: =IF( (MAX(H$3,$G24)*$C$16)<(48*(MIN(H$3,$G24))^2*$C$15/$C$14/$C$13),"Pass","Fail") -> Fail | I24: =IF( (MAX(I$3,$G24)*$C$16)<(48*(MIN(I$3,$G24))^2*$C$15/$C$14/$C$13),"Pass","Fail") -> Fail | J24: =IF( (MAX(J$3,$G24)*$C$16)<(48*(MIN(J$3,$G24))^2*$C$15/$C$14/$C$13),"Pass","Fail") -> Fail | K24: =IF( (MAX(K$3,$G24)*$C$16)<(48*(MIN(K$3,$G24))^2*$C$15/$C$14/$C$13),"Pass","Fail") -> Fail | L24: =IF( (MAX(L$3,$G24)*$C$16)<(48*(MIN(L$3,$G24))^2*$C$15/$C$14/$C$13),"Pass","Fail") -> Fail | M24: =IF( (MAX(M$3,$G24)*$C$16)<(48*(MIN(M$3,$G24))^2*$C$15/$C$14/$C$13),"Pass","Fail") -> Fail | N24: =IF( (MAX(N$3,$G24)*$C$16)<(48*(MIN(N$3,$G24))^2*$C$15/$C$14/$C$13),"Pass","Fail") -> Fail | O24: =IF( (MAX(O$3,$G24)*$C$16)<(48*(MIN(O$3,$G24))^2*$C$15/$C$14/$C$13),"Pass","Fail") -> Fail | ... BD24: =IF( (MAX(BD$3,$G24)*$C$16)<(48*(MIN(BD$3,$G24))^2*$C$15/$C$14/$C$13),"Pass","Fail") -> Pass
G25: =G24+1 -> 13 | H25: =IF( (MAX(H$3,$G25)*$C$16)<(48*(MIN(H$3,$G25))^2*$C$15/$C$14/$C$13),"Pass","Fail") -> Fail | I25: =IF( (MAX(I$3,$G25)*$C$16)<(48*(MIN(I$3,$G25))^2*$C$15/$C$14/$C$13),"Pass","Fail") -> Fail | J25: =IF( (MAX(J$3,$G25)*$C$16)<(48*(MIN(J$3,$G25))^2*$C$15/$C$14/$C$13),"Pass","Fail") -> Fail | K25: =IF( (MAX(K$3,$G25)*$C$16)<(48*(MIN(K$3,$G25))^2*$C$15/$C$14/$C$13),"Pass","Fail") -> Fail | L25: =IF( (MAX(L$3,$G25)*$C$16)<(48*(MIN(L$3,$G25))^2*$C$15/$C$14/$C$13),"Pass","Fail") -> Fail | M25: =IF( (MAX(M$3,$G25)*$C$16)<(48*(MIN(M$3,$G25))^2*$C$15/$C$14/$C$13),"Pass","Fail") -> Fail | N25: =IF( (MAX(N$3,$G25)*$C$16)<(48*(MIN(N$3,$G25))^2*$C$15/$C$14/$C$13),"Pass","Fail") -> Fail | O25: =IF( (MAX(O$3,$G25)*$C$16)<(48*(MIN(O$3,$G25))^2*$C$15/$C$14/$C$13),"Pass","Fail") -> Fail | ... BD25: =IF( (MAX(BD$3,$G25)*$C$16)<(48*(MIN(BD$3,$G25))^2*$C$15/$C$14/$C$13),"Pass","Fail") -> Pass
G26: =G25+1 -> 14 | H26: =IF( (MAX(H$3,$G26)*$C$16)<(48*(MIN(H$3,$G26))^2*$C$15/$C$14/$C$13),"Pass","Fail") -> Fail | I26: =IF( (MAX(I$3,$G26)*$C$16)<(48*(MIN(I$3,$G26))^2*$C$15/$C$14/$C$13),"Pass","Fail") -> Fail | J26: =IF( (MAX(J$3,$G26)*$C$16)<(48*(MIN(J$3,$G26))^2*$C$15/$C$14/$C$13),"Pass","Fail") -> Fail | K26: =IF( (MAX(K$3,$G26)*$C$16)<(48*(MIN(K$3,$G26))^2*$C$15/$C$14/$C$13),"Pass","Fail") -> Fail | L26: =IF( (MAX(L$3,$G26)*$C$16)<(48*(MIN(L$3,$G26))^2*$C$15/$C$14/$C$13),"Pass","Fail") -> Fail | M26: =IF( (MAX(M$3,$G26)*$C$16)<(48*(MIN(M$3,$G26))^2*$C$15/$C$14/$C$13),"Pass","Fail") -> Fail | N26: =IF( (MAX(N$3,$G26)*$C$16)<(48*(MIN(N$3,$G26))^2*$C$15/$C$14/$C$13),"Pass","Fail") -> Fail | O26: =IF( (MAX(O$3,$G26)*$C$16)<(48*(MIN(O$3,$G26))^2*$C$15/$C$14/$C$13),"Pass","Fail") -> Fail | ... BD26: =IF( (MAX(BD$3,$G26)*$C$16)<(48*(MIN(BD$3,$G26))^2*$C$15/$C$14/$C$13),"Pass","Fail") -> Pass
G27: =G26+1 -> 15 | H27: =IF( (MAX(H$3,$G27)*$C$16)<(48*(MIN(H$3,$G27))^2*$C$15/$C$14/$C$13),"Pass","Fail") -> Fail | I27: =IF( (MAX(I$3,$G27)*$C$16)<(48*(MIN(I$3,$G27))^2*$C$15/$C$14/$C$13),"Pass","Fail") -> Fail | J27: =IF( (MAX(J$3,$G27)*$C$16)<(48*(MIN(J$3,$G27))^2*$C$15/$C$14/$C$13),"Pass","Fail") -> Fail | K27: =IF( (MAX(K$3,$G27)*$C$16)<(48*(MIN(K$3,$G27))^2*$C$15/$C$14/$C$13),"Pass","Fail") -> Fail | L27: =IF( (MAX(L$3,$G27)*$C$16)<(48*(MIN(L$3,$G27))^2*$C$15/$C$14/$C$13),"Pass","Fail") -> Fail | M27: =IF( (MAX(M$3,$G27)*$C$16)<(48*(MIN(M$3,$G27))^2*$C$15/$C$14/$C$13),"Pass","Fail") -> Fail | N27: =IF( (MAX(N$3,$G27)*$C$16)<(48*(MIN(N$3,$G27))^2*$C$15/$C$14/$C$13),"Pass","Fail") -> Fail | O27: =IF( (MAX(O$3,$G27)*$C$16)<(48*(MIN(O$3,$G27))^2*$C$15/$C$14/$C$13),"Pass","Fail") -> Fail | ... BD27: =IF( (MAX(BD$3,$G27)*$C$16)<(48*(MIN(BD$3,$G27))^2*$C$15/$C$14/$C$13),"Pass","Fail") -> Pass
G28: =G27+1 -> 16 | H28: =IF( (MAX(H$3,$G28)*$C$16)<(48*(MIN(H$3,$G28))^2*$C$15/$C$14/$C$13),"Pass","Fail") -> Fail | I28: =IF( (MAX(I$3,$G28)*$C$16)<(48*(MIN(I$3,$G28))^2*$C$15/$C$14/$C$13),"Pass","Fail") -> Fail | J28: =IF( (MAX(J$3,$G28)*$C$16)<(48*(MIN(J$3,$G28))^2*$C$15/$C$14/$C$13),"Pass","Fail") -> Fail | K28: =IF( (MAX(K$3,$G28)*$C$16)<(48*(MIN(K$3,$G28))^2*$C$15/$C$14/$C$13),"Pass","Fail") -> Fail | L28: =IF( (MAX(L$3,$G28)*$C$16)<(48*(MIN(L$3,$G28))^2*$C$15/$C$14/$C$13),"Pass","Fail") -> Fail | M28: =IF( (MAX(M$3,$G28)*$C$16)<(48*(MIN(M$3,$G28))^2*$C$15/$C$14/$C$13),"Pass","Fail") -> Fail | N28: =IF( (MAX(N$3,$G28)*$C$16)<(48*(MIN(N$3,$G28))^2*$C$15/$C$14/$C$13),"Pass","Fail") -> Fail | O28: =IF( (MAX(O$3,$G28)*$C$16)<(48*(MIN(O$3,$G28))^2*$C$15/$C$14/$C$13),"Pass","Fail") -> Fail | ... BD28: =IF( (MAX(BD$3,$G28)*$C$16)<(48*(MIN(BD$3,$G28))^2*$C$15/$C$14/$C$13),"Pass","Fail") -> Pass
G29: =G28+1 -> 17 | H29: =IF( (MAX(H$3,$G29)*$C$16)<(48*(MIN(H$3,$G29))^2*$C$15/$C$14/$C$13),"Pass","Fail") -> Fail | I29: =IF( (MAX(I$3,$G29)*$C$16)<(48*(MIN(I$3,$G29))^2*$C$15/$C$14/$C$13),"Pass","Fail") -> Fail | J29: =IF( (MAX(J$3,$G29)*$C$16)<(48*(MIN(J$3,$G29))^2*$C$15/$C$14/$C$13),"Pass","Fail") -> Fail | K29: =IF( (MAX(K$3,$G29)*$C$16)<(48*(MIN(K$3,$G29))^2*$C$15/$C$14/$C$13),"Pass","Fail") -> Fail | L29: =IF( (MAX(L$3,$G29)*$C$16)<(48*(MIN(L$3,$G29))^2*$C$15/$C$14/$C$13),"Pass","Fail") -> Fail | M29: =IF( (MAX(M$3,$G29)*$C$16)<(48*(MIN(M$3,$G29))^2*$C$15/$C$14/$C$13),"Pass","Fail") -> Fail | N29: =IF( (MAX(N$3,$G29)*$C$16)<(48*(MIN(N$3,$G29))^2*$C$15/$C$14/$C$13),"Pass","Fail") -> Fail | O29: =IF( (MAX(O$3,$G29)*$C$16)<(48*(MIN(O$3,$G29))^2*$C$15/$C$14/$C$13),"Pass","Fail") -> Fail | ... BD29: =IF( (MAX(BD$3,$G29)*$C$16)<(48*(MIN(BD$3,$G29))^2*$C$15/$C$14/$C$13),"Pass","Fail") -> Pass
G30: =G29+1 -> 18 | H30: =IF( (MAX(H$3,$G30)*$C$16)<(48*(MIN(H$3,$G30))^2*$C$15/$C$14/$C$13),"Pass","Fail") -> Fail | I30: =IF( (MAX(I$3,$G30)*$C$16)<(48*(MIN(I$3,$G30))^2*$C$15/$C$14/$C$13),"Pass","Fail") -> Fail | J30: =IF( (MAX(J$3,$G30)*$C$16)<(48*(MIN(J$3,$G30))^2*$C$15/$C$14/$C$13),"Pass","Fail") -> Fail | K30: =IF( (MAX(K$3,$G30)*$C$16)<(48*(MIN(K$3,$G30))^2*$C$15/$C$14/$C$13),"Pass","Fail") -> Fail | L30: =IF( (MAX(L$3,$G30)*$C$16)<(48*(MIN(L$3,$G30))^2*$C$15/$C$14/$C$13),"Pass","Fail") -> Fail | M30: =IF( (MAX(M$3,$G30)*$C$16)<(48*(MIN(M$3,$G30))^2*$C$15/$C$14/$C$13),"Pass","Fail") -> Fail | N30: =IF( (MAX(N$3,$G30)*$C$16)<(48*(MIN(N$3,$G30))^2*$C$15/$C$14/$C$13),"Pass","Fail") -> Fail | O30: =IF( (MAX(O$3,$G30)*$C$16)<(48*(MIN(O$3,$G30))^2*$C$15/$C$14/$C$13),"Pass","Fail") -> Fail | ... BD30: =IF( (MAX(BD$3,$G30)*$C$16)<(48*(MIN(BD$3,$G30))^2*$C$15/$C$14/$C$13),"Pass","Fail") -> Pass
G31: =G30+1 -> 19 | H31: =IF( (MAX(H$3,$G31)*$C$16)<(48*(MIN(H$3,$G31))^2*$C$15/$C$14/$C$13),"Pass","Fail") -> Fail | I31: =IF( (MAX(I$3,$G31)*$C$16)<(48*(MIN(I$3,$G31))^2*$C$15/$C$14/$C$13),"Pass","Fail") -> Fail | J31: =IF( (MAX(J$3,$G31)*$C$16)<(48*(MIN(J$3,$G31))^2*$C$15/$C$14/$C$13),"Pass","Fail") -> Fail | K31: =IF( (MAX(K$3,$G31)*$C$16)<(48*(MIN(K$3,$G31))^2*$C$15/$C$14/$C$13),"Pass","Fail") -> Fail | L31: =IF( (MAX(L$3,$G31)*$C$16)<(48*(MIN(L$3,$G31))^2*$C$15/$C$14/$C$13),"Pass","Fail") -> Fail | M31: =IF( (MAX(M$3,$G31)*$C$16)<(48*(MIN(M$3,$G31))^2*$C$15/$C$14/$C$13),"Pass","Fail") -> Fail | N31: =IF( (MAX(N$3,$G31)*$C$16)<(48*(MIN(N$3,$G31))^2*$C$15/$C$14/$C$13),"Pass","Fail") -> Fail | O31: =IF( (MAX(O$3,$G31)*$C$16)<(48*(MIN(O$3,$G31))^2*$C$15/$C$14/$C$13),"Pass","Fail") -> Fail | ... BD31: =IF( (MAX(BD$3,$G31)*$C$16)<(48*(MIN(BD$3,$G31))^2*$C$15/$C$14/$C$13),"Pass","Fail") -> Pass
G32: =G31+1 -> 20 | H32: =IF( (MAX(H$3,$G32)*$C$16)<(48*(MIN(H$3,$G32))^2*$C$15/$C$14/$C$13),"Pass","Fail") -> Fail | I32: =IF( (MAX(I$3,$G32)*$C$16)<(48*(MIN(I$3,$G32))^2*$C$15/$C$14/$C$13),"Pass","Fail") -> Fail | J32: =IF( (MAX(J$3,$G32)*$C$16)<(48*(MIN(J$3,$G32))^2*$C$15/$C$14/$C$13),"Pass","Fail") -> Fail | K32: =IF( (MAX(K$3,$G32)*$C$16)<(48*(MIN(K$3,$G32))^2*$C$15/$C$14/$C$13),"Pass","Fail") -> Fail | L32: =IF( (MAX(L$3,$G32)*$C$16)<(48*(MIN(L$3,$G32))^2*$C$15/$C$14/$C$13),"Pass","Fail") -> Fail | M32: =IF( (MAX(M$3,$G32)*$C$16)<(48*(MIN(M$3,$G32))^2*$C$15/$C$14/$C$13),"Pass","Fail") -> Fail | N32: =IF( (MAX(N$3,$G32)*$C$16)<(48*(MIN(N$3,$G32))^2*$C$15/$C$14/$C$13),"Pass","Fail") -> Fail | O32: =IF( (MAX(O$3,$G32)*$C$16)<(48*(MIN(O$3,$G32))^2*$C$15/$C$14/$C$13),"Pass","Fail") -> Fail | ... BD32: =IF( (MAX(BD$3,$G32)*$C$16)<(48*(MIN(BD$3,$G32))^2*$C$15/$C$14/$C$13),"Pass","Fail") -> Pass
G33: =G32+1 -> 21 | H33: =IF( (MAX(H$3,$G33)*$C$16)<(48*(MIN(H$3,$G33))^2*$C$15/$C$14/$C$13),"Pass","Fail") -> Fail | I33: =IF( (MAX(I$3,$G33)*$C$16)<(48*(MIN(I$3,$G33))^2*$C$15/$C$14/$C$13),"Pass","Fail") -> Fail | J33: =IF( (MAX(J$3,$G33)*$C$16)<(48*(MIN(J$3,$G33))^2*$C$15/$C$14/$C$13),"Pass","Fail") -> Fail | K33: =IF( (MAX(K$3,$G33)*$C$16)<(48*(MIN(K$3,$G33))^2*$C$15/$C$14/$C$13),"Pass","Fail") -> Fail | L33: =IF( (MAX(L$3,$G33)*$C$16)<(48*(MIN(L$3,$G33))^2*$C$15/$C$14/$C$13),"Pass","Fail") -> Fail | M33: =IF( (MAX(M$3,$G33)*$C$16)<(48*(MIN(M$3,$G33))^2*$C$15/$C$14/$C$13),"Pass","Fail") -> Fail | N33: =IF( (MAX(N$3,$G33)*$C$16)<(48*(MIN(N$3,$G33))^2*$C$15/$C$14/$C$13),"Pass","Fail") -> Fail | O33: =IF( (MAX(O$3,$G33)*$C$16)<(48*(MIN(O$3,$G33))^2*$C$15/$C$14/$C$13),"Pass","Fail") -> Fail | ... BD33: =IF( (MAX(BD$3,$G33)*$C$16)<(48*(MIN(BD$3,$G33))^2*$C$15/$C$14/$C$13),"Pass","Fail") -> Pass
G34: =G33+1 -> 22 | H34: =IF( (MAX(H$3,$G34)*$C$16)<(48*(MIN(H$3,$G34))^2*$C$15/$C$14/$C$13),"Pass","Fail") -> Fail | I34: =IF( (MAX(I$3,$G34)*$C$16)<(48*(MIN(I$3,$G34))^2*$C$15/$C$14/$C$13),"Pass","Fail") -> Fail | J34: =IF( (MAX(J$3,$G34)*$C$16)<(48*(MIN(J$3,$G34))^2*$C$15/$C$14/$C$13),"Pass","Fail") -> Fail | K34: =IF( (MAX(K$3,$G34)*$C$16)<(48*(MIN(K$3,$G34))^2*$C$15/$C$14/$C$13),"Pass","Fail") -> Fail | L34: =IF( (MAX(L$3,$G34)*$C$16)<(48*(MIN(L$3,$G34))^2*$C$15/$C$14/$C$13),"Pass","Fail") -> Fail | M34: =IF( (MAX(M$3,$G34)*$C$16)<(48*(MIN(M$3,$G34))^2*$C$15/$C$14/$C$13),"Pass","Fail") -> Fail | N34: =IF( (MAX(N$3,$G34)*$C$16)<(48*(MIN(N$3,$G34))^2*$C$15/$C$14/$C$13),"Pass","Fail") -> Fail | O34: =IF( (MAX(O$3,$G34)*$C$16)<(48*(MIN(O$3,$G34))^2*$C$15/$C$14/$C$13),"Pass","Fail") -> Fail | ... BD34: =IF( (MAX(BD$3,$G34)*$C$16)<(48*(MIN(BD$3,$G34))^2*$C$15/$C$14/$C$13),"Pass","Fail") -> Pass
G35: =G34+1 -> 23 | H35: =IF( (MAX(H$3,$G35)*$C$16)<(48*(MIN(H$3,$G35))^2*$C$15/$C$14/$C$13),"Pass","Fail") -> Fail | I35: =IF( (MAX(I$3,$G35)*$C$16)<(48*(MIN(I$3,$G35))^2*$C$15/$C$14/$C$13),"Pass","Fail") -> Fail | J35: =IF( (MAX(J$3,$G35)*$C$16)<(48*(MIN(J$3,$G35))^2*$C$15/$C$14/$C$13),"Pass","Fail") -> Fail | K35: =IF( (MAX(K$3,$G35)*$C$16)<(48*(MIN(K$3,$G35))^2*$C$15/$C$14/$C$13),"Pass","Fail") -> Fail | L35: =IF( (MAX(L$3,$G35)*$C$16)<(48*(MIN(L$3,$G35))^2*$C$15/$C$14/$C$13),"Pass","Fail") -> Fail | M35: =IF( (MAX(M$3,$G35)*$C$16)<(48*(MIN(M$3,$G35))^2*$C$15/$C$14/$C$13),"Pass","Fail") -> Fail | N35: =IF( (MAX(N$3,$G35)*$C$16)<(48*(MIN(N$3,$G35))^2*$C$15/$C$14/$C$13),"Pass","Fail") -> Fail | O35: =IF( (MAX(O$3,$G35)*$C$16)<(48*(MIN(O$3,$G35))^2*$C$15/$C$14/$C$13),"Pass","Fail") -> Fail | ... BD35: =IF( (MAX(BD$3,$G35)*$C$16)<(48*(MIN(BD$3,$G35))^2*$C$15/$C$14/$C$13),"Pass","Fail") -> Pass
G36: =G35+1 -> 24 | H36: =IF( (MAX(H$3,$G36)*$C$16)<(48*(MIN(H$3,$G36))^2*$C$15/$C$14/$C$13),"Pass","Fail") -> Fail | I36: =IF( (MAX(I$3,$G36)*$C$16)<(48*(MIN(I$3,$G36))^2*$C$15/$C$14/$C$13),"Pass","Fail") -> Fail | J36: =IF( (MAX(J$3,$G36)*$C$16)<(48*(MIN(J$3,$G36))^2*$C$15/$C$14/$C$13),"Pass","Fail") -> Fail | K36: =IF( (MAX(K$3,$G36)*$C$16)<(48*(MIN(K$3,$G36))^2*$C$15/$C$14/$C$13),"Pass","Fail") -> Fail | L36: =IF( (MAX(L$3,$G36)*$C$16)<(48*(MIN(L$3,$G36))^2*$C$15/$C$14/$C$13),"Pass","Fail") -> Fail | M36: =IF( (MAX(M$3,$G36)*$C$16)<(48*(MIN(M$3,$G36))^2*$C$15/$C$14/$C$13),"Pass","Fail") -> Fail | N36: =IF( (MAX(N$3,$G36)*$C$16)<(48*(MIN(N$3,$G36))^2*$C$15/$C$14/$C$13),"Pass","Fail") -> Fail | O36: =IF( (MAX(O$3,$G36)*$C$16)<(48*(MIN(O$3,$G36))^2*$C$15/$C$14/$C$13),"Pass","Fail") -> Fail | ... BD36: =IF( (MAX(BD$3,$G36)*$C$16)<(48*(MIN(BD$3,$G36))^2*$C$15/$C$14/$C$13),"Pass","Fail") -> Pass
... G52: =G51+1 -> 40 | H52: =IF( (MAX(H$3,$G52)*$C$16)<(48*(MIN(H$3,$G52))^2*$C$15/$C$14/$C$13),"Pass","Fail") -> Fail | I52: =IF( (MAX(I$3,$G52)*$C$16)<(48*(MIN(I$3,$G52))^2*$C$15/$C$14/$C$13),"Pass","Fail") -> Fail | J52: =IF( (MAX(J$3,$G52)*$C$16)<(48*(MIN(J$3,$G52))^2*$C$15/$C$14/$C$13),"Pass","Fail") -> Fail | K52: =IF( (MAX(K$3,$G52)*$C$16)<(48*(MIN(K$3,$G52))^2*$C$15/$C$14/$C$13),"Pass","Fail") -> Fail | L52: =IF( (MAX(L$3,$G52)*$C$16)<(48*(MIN(L$3,$G52))^2*$C$15/$C$14/$C$13),"Pass","Fail") -> Fail | M52: =IF( (MAX(M$3,$G52)*$C$16)<(48*(MIN(M$3,$G52))^2*$C$15/$C$14/$C$13),"Pass","Fail") -> Fail | N52: =IF( (MAX(N$3,$G52)*$C$16)<(48*(MIN(N$3,$G52))^2*$C$15/$C$14/$C$13),"Pass","Fail") -> Fail | O52: =IF( (MAX(O$3,$G52)*$C$16)<(48*(MIN(O$3,$G52))^2*$C$15/$C$14/$C$13),"Pass","Fail") -> Fail | ... BD52: =IF( (MAX(BD$3,$G52)*$C$16)<(48*(MIN(BD$3,$G52))^2*$C$15/$C$14/$C$13),"Pass","Fail") -> Pass

Sheet Diameter data
C2: Temp °F | D2: Index | E2: Lower °F | F2: Upper °F | G2: Ratio | H2: Exp @ Lower | I2: Exp @ Upper | J2: in/100ft | K2: mm/m
B3: Expansion | C3: =Master!C12 -> 400 | D3: =IFERROR(MATCH(C3,'Thermal Co-efficient data'!C8:C86),"ERROR") -> 35 | E3: =IFERROR(INDEX('Thermal Co-efficient data'!C8:C86,D3),"ERROR") -> 400 | F3: =IFERROR(INDEX('Thermal Co-efficient data'!C8:C86,D3+1),"ERROR") -> 425 | G3: =IFERROR((C3-E3)/(F3-E3),"ERROR") -> 0 | H3: =H6 -> 3.8 | I3: =H9 -> 4.1 | J3: =IFERROR(H3+(I3-H3)*G3,"ERROR") -> 3.8 | K3: =IFERROR(ROUNDUP(J3*25.4/100/0.3048,3),"ERROR") -> 3.167
G5: Temp., °F | H5: =Master!C11 -> Austenitic Stainless Steels 18Cr-8Ni
G6: =E3 -> 400 | H6: =DGET('Thermal Co-efficient data'!C7:Y86,H5,G5:G6) -> 3.8
G8: Temp., °F | H8: =Master!C11 -> Austenitic Stainless Steels 18Cr-8Ni
G9: =F3 -> 425 | H9: =DGET('Thermal Co-efficient data'!C7:Y86,H8,G8:G9) -> 4.1
B11: NS | C11: OD
B12: ½" - 15 | C12: 21.336
B13: ¾" - 20 | C13: 26.67
B14: 1" - 25 | C14: 33.401
B15: 1¼" - 32 | C15: 42.164
B16: 1½" - 40 | C16: 48.26
B17: 2" - 50 | C17: 60.325
B18: 2½" - 65 | C18: 73.025
B19: 3" - 80 | C19: 88.9
B20: 3½" - 90 | C20: 101.6
B21: 4" - 100 | C21: 114.3
B22: 5" - 125 | C22: 127
B23: 6" - 150 | C23: 168.275
... B53: 80" - 2000 | C53: 2032

Sheet Thermal Co-efficient data
A1: 0 | B1: 1 | C1: ASME B31.3-2010 | D1: 0 | E1: 0 | F1: 0 | G1: 0 | H1: 0 | I1: 0 | J1: 0 | K1: 0 | L1: 0 | M1: 0 | N1: 0 | O1: 0 | P1: 0 | Q1: 0 | R1: 0 | S1: 0 | T1: 0 | U1: 0 | V1: 0 | W1: 0 | X1: 0 | Y1: 0 | Z1: 0 | AA1: 0
A2: 0 | B2: 2 | C2: 0 | D2: 0 | E2: 0 | F2: 0 | G2: 0 | H2: 0 | I2: 0 | J2: 0 | K2: 0 | L2: 0 | M2: 0 | N2: 0 | O2: 0 | P2: 0 | Q2: 0 | R2: 0 | S2: 0 | T2: 0 | U2: 0 | V2: 0 | W2: 0 | X2: 0 | Y2: 0 | Z2: 0 | AA2: 0
A3: 0 | B3: 3 | C3: 0 | D3: 0 | E3: 0 | F3: 0 | G3: 0 | H3: 0 | I3: 0 | J3: 0 | K3: 0 | L3: 0 | M3: 0 | N3: 0 | O3: 0 | P3: 0 | Q3: 0 | R3: 0 | S3: 0 | T3: 0 | U3: 0 | V3: 0 | W3: 0 | X3: 0 | Y3: 0 | Z3: 0 | AA3: 0
A4: (10) | B4: 4 | C4: Table C-1 Total Thermal Expansion, U.S. Units, for Metals | D4: 0 | E4: 0 | F4: 0 | G4: 0 | H4: 0 | I4: 0 | J4: 0 | K4: 0 | L4: 0 | M4: 0 | N4: 0 | O4: 0 | P4: 0 | Q4: 0 | R4: 0 | S4: 0 | T4: 0 | U4: 0 | V4: 0 | W4: 0 | X4: 0 | Y4: 0 | Z4: 0 | AA4: 0
A5: 0 | B5: 5 | C5: Total Linear Thermal Expansion Between 70°F and Indicated Temperature, in./100 ft | D5: 0 | E5: 0 | F5: 0 | G5: 0 | H5: 0 | I5: 0 | J5: 0 | K5: 0 | L5: 0 | M5: 0 | N5: 0 | O5: 0 | P5: 0 | Q5: 0 | R5: 0 | S5: 0 | T5: 0 | U5: 0 | V5: 0 | W5: 0 | X5: 0 | Y5: 0 | Z5: 0 | AA5: 0
A6: 0 | B6: 6 | C6: 0 | D6: Material | E6: 0 | F6: 0 | G6: 0 | H6: 0 | I6: 0 | J6: 0 | K6: 0 | L6: 0 | M6: 0 | N6: 0 | O6: 0 | P6: 0 | Q6: 0 | R6: 0 | S6: 0 | T6: 0 | U6: 0 | V6: 0 | W6: 0 | X6: 0 | Y6: 0 | Z6: 0 | AA6: 0
A7: 0 | B7: 7 | C7: Temp., °F | D7: Carbon Steel Carbon-Moly-Low-Chrome (Through 3Cr-Mo) | E7: 5Cr-Mo Through 9Cr-Mo | F7: Austenitic Stainless Steels 18Cr-8Ni | G7: 12Cr, 17Cr, 27Cr | H7: 25Cr-20Ni | I7: UNS N04400 67Ni-30Cu | J7: 3½Ni | K7: Copper and Copper Alloys | L7: Titanium Gr. 1,2,3,7, 11,12,16,17 | M7: Titanium Gr. 9 | N7: UNS N10675 | O7: Aluminium | P7: Gray Cast Iron | Q7: Bronze | R7: Brass | S7: 70Cu-30Ni | T7: UNS N08XXX Series Ni-Fe-Cr | U7: UNS N06XXX Series Ni-Cr-Fe | V7: UNS N06035 Series Ni-Cr-Mo | W7: UNS N06200 Ni-Cr-Mo | X7: Ductile Iron | Y7: Invar 36Ni | Z7: 0 | AA7: 0
A8: 0 | B8: 8 | C8: -450 | D8: - | E8: - | F8: - | G8: - | H8: - | I8: - | J8: - | K8: -3.93 | L8: - | M8: - | N8: - | O8: - | P8: - | Q8: - | R8: - | S8: - | T8: - | U8: - | V8: - | W8: - | X8: - | Y8: - | Z8: 0 | AA8: 0
A9: 0 | B9: 9 | C9: -425 | D9: - | E9: - | F9: - | G9: - | H9: - | I9: - | J9: - | K9: -3.93 | L9: - | M9: - | N9: - | O9: - | P9: - | Q9: - | R9: - | S9: - | T9: - | U9: - | V9: - | W9: - | X9: - | Y9: -0.48 | Z9: 0 | AA9: 0
A10: 0 | B10: 10 | C10: -400 | D10: - | E10: - | F10: - | G10: - | H10: - | I10: - | J10: - | K10: -3.91 | L10: - | M10: - | N10: - | O10: - | P10: - | Q10: - | R10: - | S10: - | T10: - | U10: - | V10: - | W10: - | X10: - | Y10: -0.48 | Z10: 0 | AA10: 0
A11: 0 | B11: 11 | C11: -375 | D11: - | E11: - | F11: - | G11: - | H11: - | I11: - | J11: - | K11: -3.87 | L11: - | M11: - | N11: - | O11: - | P11: - | Q11: - | R11: - | S11: - | T11: - | U11: - | V11: - | W11: - | X11: - | Y11: -0.48 | Z11: 0 | AA11: 0
A12: 0 | B12: 12 | C12: -350 | D12: - | E12: - | F12: - | G12: - | H12: - | I12: - | J12: - | K12: -3.79 | L12: - | M12: - | N12: - | O12: - | P12: - | Q12: - | R12: - | S12: - | T12: - | U12: - | V12: - | W12: - | X12: - | Y12: -0.48 | Z12: 0 | AA12: 0
A13: 0 | B13: 14 | C13: -325 | D13: -2.37 | E13: -2.22 | F13: -3.85 | G13: -2.04 | H13: - | I13: -2.62 | J13: -2.25 | K13: -3.67 | L13: - | M13: - | N13: - | O13: -4.68 | P13: - | Q13: -3.98 | R13: -3.88 | S13: -3.15 | T13: - | U13: - | V13: - | W13: - | X13: - | Y13: -0.47 | Z13: 0 | AA13: 0
A14: 0 | B14: 15 | C14: -300 | D14: -2.24 | E14: -2.1 | F14: -3.63 | G14: -1.92 | H14: - | I14: -2.5 | J14: -2.17 | K14: -3.53 | L14: - | M14: - | N14: - | O14: -4.46 | P14: - | Q14: -3.74 | R14: -3.64 | S14: -2.87 | T14: - | U14: - | V14: - | W14: - | X14: - | Y14: -0.44 | Z14: 0 | AA14: 0
A15: 0 | B15: 16 | C15: -275 | D15: -2.11 | E15: -1.98 | F15: -3.41 | G15: -1.8 | H15: - | I15: -2.38 | J15: -2.07 | K15: -3.36 | L15: - | M15: - | N15: - | O15: -4.21 | P15: - | Q15: -3.5 | R15: -3.4 | S15: -2.7 | T15: - | U15: - | V15: - | W15: - | X15: - | Y15: -0.42 | Z15: 0 | AA15: 0
A16: 0 | B16: 17 | C16: -250 | D16: -1.98 | E16: -1.86 | F16: -3.19 | G16: -1.68 | H16: - | I16: -2.26 | J16: -1.96 | K16: -3.17 | L16: - | M16: - | N16: - | O16: -3.97 | P16: - | Q16: -3.26 | R16: -3.16 | S16: -2.53 | T16: - | U16: - | V16: - | W16: - | X16: - | Y16: -0.38 | Z16: 0 | AA16: 0
A17: 0 | B17: 19 | C17: -225 | D17: -1.85 | E17: -1.74 | F17: -2.96 | G17: -1.57 | H17: - | I17: -2.14 | J17: -1.86 | K17: -2.97 | L17: - | M17: - | N17: - | O17: -3.71 | P17: - | Q17: -3.02 | R17: -2.93 | S17: -2.36 | T17: - | U17: - | V17: - | W17: - | X17: - | Y17: -0.35 | Z17: 0 | AA17: 0
A18: 0 | B18: 20 | C18: -200 | D18: -1.71 | E18: -1.62 | F18: -2.73 | G18: -1.46 | H18: - | I18: -2.02 | J18: -1.76 | K18: -2.76 | L18: - | M18: - | N18: - | O18: -3.44 | P18: - | Q18: -2.78 | R18: -2.7 | S18: -2.19 | T18: - | U18: - | V18: - | W18: - | X18: -1.51 | Y18: -0.31 | Z18: 0 | AA18: 0
A19: 0 | B19: 21 | C19: -175 | D19: -1.58 | E19: -1.5 | F19: -2.5 | G19: -1.35 | H19: - | I19: -1.9 | J19: -1.62 | K19: -2.53 | L19: - | M19: - | N19: - | O19: -3.16 | P19: - | Q19: -2.54 | R19: -2.47 | S19: -2.12 | T19: - | U19: - | V19: - | W19: - | X19: -1.41 | Y19: -0.28 | Z19: 0 | AA19: 0
A20: 0 | B20: 22 | C20: -150 | D20: -1.45 | E20: -1.37 | F20: -2.27 | G20: -1.24 | H20: - | I20: -1.79 | J20: -1.48 | K20: -2.3 | L20: - | M20: - | N20: - | O20: -2.88 | P20: - | Q20: -2.31 | R20: -2.24 | S20: -1.95 | T20: - | U20: - | V20: - | W20: - | X20: -1.29 | Y20: -0.24 | Z20: 0 | AA20: 0
A21: 0 | B21: 24 | C21: -125 | D21: -1.3 | E21: -1.23 | F21: -2.01 | G21: -1.11 | H21: - | I21: -1.59 | J21: -1.33 | K21: -2.06 | L21: - | M21: - | N21: - | O21: -2.57 | P21: - | Q21: -2.06 | R21: -2 | S21: -1.74 | T21: - | U21: - | V21: - | W21: - | X21: -1.16 | Y21: -0.2 | Z21: 0 | AA21: 0
A22: 0 | B22: 25 | C22: -100 | D22: -1.15 | E22: -1.08 | F22: -1.75 | G22: -0.98 | H22: - | I22: -1.38 | J22: -1.17 | K22: -1.81 | L22: - | M22: - | N22: - | O22: -2.27 | P22: - | Q22: -1.81 | R22: -1.76 | S22: -1.53 | T22: - | U22: - | V22: - | W22: - | X22: -1.04 | Y22: -0.18 | Z22: 0 | AA22: 0
A23: 0 | B23: 26 | C23: -75 | D23: -1 | E23: -0.94 | F23: -1.5 | G23: -0.85 | H23: - | I23: -1.18 | J23: -1.01 | K23: -1.56 | L23: - | M23: - | N23: - | O23: -1.97 | P23: - | Q23: -1.56 | R23: -1.52 | S23: -1.33 | T23: - | U23: - | V23: - | W23: - | X23: -0.91 | Y23: -0.16 | Z23: 0 | AA23: 0
A24: 0 | B24: 27 | C24: -50 | D24: -0.84 | E24: -0.79 | F24: -1.24 | G24: -0.72 | H24: - | I24: -0.98 | J24: -0.84 | K24: -1.3 | L24: - | M24: - | N24: - | O24: -1.67 | P24: - | Q24: -1.32 | R24: -1.29 | S24: -1.13 | T24: - | U24: - | V24: - | W24: - | X24: -0.77 | Y24: -0.12 | Z24: 0 | AA24: 0
A25: 0 | B25: 29 | C25: -25 | D25: -0.68 | E25: -0.63 | F25: -0.98 | G25: -0.57 | H25: - | I25: -0.77 | J25: -0.67 | K25: -1.04 | L25: - | M25: - | N25: - | O25: -1.32 | P25: - | Q25: -1.25 | R25: -1.02 | S25: -0.89 | T25: - | U25: - | V25: - | W25: - | X25: -0.62 | Y25: -0.08 | Z25: 0 | AA25: 0
A26: 0 | B26: 30 | C26: 0 | D26: -0.49 | E26: -0.46 | F26: -0.72 | G26: -0.42 | H26: - | I26: -0.57 | J26: -0.5 | K26: -0.77 | L26: - | M26: - | N26: - | O26: -0.97 | P26: - | Q26: -0.77 | R26: -0.75 | S26: -0.66 | T26: - | U26: - | V26: - | W26: - | X26: -0.46 | Y26: -0.06 | Z26: 0 | AA26: 0
A27: 0 | B27: 31 | C27: 25 | D27: -0.32 | E27: -0.3 | F27: -0.46 | G27: -0.27 | H27: - | I27: -0.37 | J27: -0.32 | K27: -0.5 | L27: - | M27: - | N27: - | O27: -0.63 | P27: - | Q27: -0.49 | R27: -0.48 | S27: -0.42 | T27: - | U27: - | V27: - | W27: - | X27: -0.23 | Y27: -0.02 | Z27: 0 | AA27: 0
A28: 0 | B28: 32 | C28: 50 | D28: -0.14 | E28: -0.13 | F28: -0.21 | G28: -0.12 | H28: - | I28: -0.2 | J28: -0.15 | K28: -0.22 | L28: - | M28: - | N28: - | O28: -0.28 | P28: - | Q28: -0.22 | R28: -0.21 | S28: -0.19 | T28: - | U28: - | V28: - | W28: - | X28: -0.14 | Y28: -0.01 | Z28: 0 | AA28: 0
A29: 0 | B29: 34 | C29: 70 | D29: 0 | E29: 0 | F29: 0 | G29: 0 | H29: 0 | I29: 0 | J29: 0 | K29: 0 | L29: 0 | M29: 0 | N29: 0 | O29: 0 | P29: 0 | Q29: 0 | R29: 0 | S29: 0 | T29: 0 | U29: 0 | V29: 0 | W29: 0 | X29: 0 | Y29: 0 | Z29: 0 | AA29: 0
A30: 0 | B30: 35 | C30: 100 | D30: 0.23 | E30: 0.22 | F30: 0.34 | G30: 0.2 | H30: 0.32 | I30: 0.28 | J30: 0.23 | K30: 0.34 | L30: 0.2 | M30: 0.2 | N30: 0.2 | O30: 0.46 | P30: 0.21 | Q30: 0.36 | R30: 0.35 | S30: 0.31 | T30: 0.28 | U30: 0.26 | V30: 0.24 | W30: 0.25 | X30: 0.21 | Y30: 0.02 | Z30: 0 | AA30: 0
A31: 0 | B31: 36 | C31: 125 | D31: 0.42 | E31: 0.4 | F31: 0.62 | G31: 0.36 | H31: 0.58 | I31: 0.52 | J31: 0.42 | K31: 0.63 | L31: 0.35 | M31: 0.35 | N31: 0.4 | O31: 0.85 | P31: 0.38 | Q31: 0.66 | R31: 0.64 | S31: 0.56 | T31: 0.52 | U31: 0.48 | V31: 0.44 | W31: 0.46 | X31: 0.39 | Y31: 0.05 | Z31: 0 | AA31: 0
A32: 0 | B32: 37 | C32: 150 | D32: 0.61 | E32: 0.58 | F32: 0.9 | G32: 0.53 | H32: 0.84 | I32: 0.75 | J32: 0.61 | K32: 0.91 | L32: 0.5 | M32: 0.5 | N32: 0.6 | O32: 1.23 | P32: 0.55 | Q32: 0.96 | R32: 0.94 | S32: 0.82 | T32: 0.76 | U32: 0.7 | V32: 0.65 | W32: 0.66 | X32: 0.57 | Y32: 0.06 | Z32: 0 | AA32: 0
A33: 0 | B33: 39 | C33: 175 | D33: 0.8 | E33: 0.76 | F33: 1.18 | G33: 0.69 | H33: 1.1 | I33: 0.99 | J33: 0.81 | K33: 1.2 | L33: 0.6 | M33: 0.65 | N33: 0.75 | O33: 1.62 | P33: 0.73 | Q33: 1.26 | R33: 1.23 | S33: 1.07 | T33: 0.99 | U33: 0.92 | V33: 0.86 | W33: 0.87 | X33: 0.76 | Y33: 0.08 | Z33: 0 | AA33: 0
A34: 0 | B34: 40 | C34: 200 | D34: 0.99 | E34: 0.94 | F34: 1.46 | G34: 0.86 | H34: 1.37 | I34: 1.22 | J34: 1.01 | K34: 1.49 | L34: 0.7 | M34: 0.8 | N34: 0.9 | O34: 2 | P34: 0.9 | Q34: 1.56 | R34: 1.52 | S34: 1.33 | T34: 1.23 | U34: 1.15 | V34: 1.06 | W34: 1.08 | X34: 0.94 | Y34: 0.1 | Z34: 0 | AA34: 0
A35: 0 | B35: 41 | C35: 225 | D35: 1.21 | E35: 1.13 | F35: 1.75 | G35: 1.03 | H35: 1.64 | I35: 1.46 | J35: 1.21 | K35: 1.79 | L35: 0.85 | M35: 0.95 | N35: 1.1 | O35: 2.41 | P35: 1.08 | Q35: 1.86 | R35: 1.83 | S35: 1.59 | T35: 1.49 | U35: 1.38 | V35: 1.27 | W35: 1.28 | X35: 1.13 | Y35: 0.13 | Z35: 0 | AA35: 0
A36: 0 | B36: 42 | C36: 250 | D36: 1.4 | E36: 1.33 | F36: 2.03 | G36: 1.21 | H36: 1.91 | I36: 1.71 | J36: 1.42 | K36: 2.09 | L36: 1 | M36: 1.1 | N36: 1.3 | O36: 2.83 | P36: 1.27 | Q36: 2.17 | R36: 2.14 | S36: 1.86 | T36: 1.76 | U36: 1.61 | V36: 1.49 | W36: 1.49 | X36: 1.33 | Y36: 0.17 | Z36: 0 | AA36: 0
A37: 0 | B37: 44 | C37: 275 | D37: 1.61 | E37: 1.52 | F37: 2.32 | G37: 1.38 | H37: 2.18 | I37: 1.96 | J37: 1.63 | K37: 2.38 | L37: 1.15 | M37: 1.25 | N37: 1.45 | O37: 3.24 | P37: 1.45 | Q37: 2.48 | R37: 2.45 | S37: 2.13 | T37: 2.03 | U37: 1.85 | V37: 1.7 | W37: 1.7 | X37: 1.53 | Y37: 0.2 | Z37: 0 | AA37: 0
A38: 0 | B38: 45 | C38: 300 | D38: 1.82 | E38: 1.71 | F38: 2.61 | G38: 1.56 | H38: 2.45 | I38: 2.21 | J38: 1.84 | K38: 2.68 | L38: 1.3 | M38: 1.4 | N38: 1.6 | O38: 3.67 | P38: 1.64 | Q38: 2.79 | R38: 2.76 | S38: 2.4 | T38: 2.3 | U38: 2.09 | V38: 1.91 | W38: 1.9 | X38: 1.72 | Y38: 0.24 | Z38: 0 | AA38: 0
A39: 0 | B39: 46 | C39: 325 | D39: 2.04 | E39: 1.9 | F39: 2.9 | G39: 1.74 | H39: 2.72 | I39: 2.44 | J39: 2.05 | K39: 2.99 | L39: 1.45 | M39: 1.55 | N39: 1.8 | O39: 4.09 | P39: 1.83 | Q39: 3.11 | R39: 3.08 | S39: 2.68 | T39: 2.59 | U39: 2.32 | V39: 2.13 | W39: 2.11 | X39: 1.93 | Y39: 0.3 | Z39: 0 | AA39: 0
A40: 0 | B40: 47 | C40: 350 | D40: 2.26 | E40: 2.1 | F40: 3.2 | G40: 1.93 | H40: 2.99 | I40: 2.68 | J40: 2.26 | K40: 3.29 | L40: 1.6 | M40: 1.7 | N40: 2 | O40: 4.52 | P40: 2.03 | Q40: 3.42 | R40: 3.41 | S40: 2.96 | T40: 2.88 | U40: 2.56 | V40: 2.35 | W40: 2.32 | X40: 2.13 | Y40: 0.36 | Z40: 0 | AA40: 0
...
